Workbook

Sheet 模型说明
A1: SP500风控模型 — 技术文档
A3: 1. 模型概述
A5: ● 是什么
A6: 一个基于多维度市场压力指标的风控仓位管理模型。它不预测市场方向，而是衡量当前市场环境的“操作难度”——即在当前条件下持有股票仓位的风险水平。当多个压力指标同时升高时，模型建议降低仓位；压力消退时恢复仓位。
A8: ● 设计哲学
A9: 模型的核心理念是“宁可踏空，不可被套”。它不试图择时（判断涨跌），而是在危险环境中主动降低暴露。代价是在牛市中因不满仓而跟不上基准（年化Alpha约-2%），收益是在熊市和危机中大幅减少损失（最大回撤从-56.2%压缩至-15.2%）。
A11: ● 不是什么
A12: • 不是择时模型：不会说“现在买”或“现在卖”，只调节仓位比例。
A13: • 不是预测模型：不预测未来收益率，只评估当前风险环境。
A14: • 不是交易策略：不包含个股选择、行业轮动、入场/出场时机等细节。
A15: • 不是实时系统：每周更新一次，下周一开盘执行，不做盘中调仓。
A17: ● 核心流程一句话
... A134: • 信号可视化：5张图表（SP500×风险信号、市场风险总览、纯评分、否决权评分、回撤深度） • _图表数据：信号可视化图表的源数据（8列×1,269行）

Sheet 模型评价
A1: 操作难度模型 — 风控有效性评价
A2: 评价视角：模型是否准确识别了不同操作难度的市场环境（非择时/收益评价）
A3: 数据范围 | B3: 评分与状态_周度 行275-1546 | 回测_周度 行262-1529
A4: 有效观测周数 | B4: =COUNTA(回测_周度!D262:D1529)
A6: 一、区分度分析 — 模型说“难”时，市场是否真的更难？
A7: 核心逻辑：如果模型的风险分级是准确的，那么被标为"高风险"的时期，市场应该确实波动更大、极端下跌更频繁。下表将1182周数据按6个风险等级分组，分别统计年化波动率、平均|周收益|、周跌>3%频率、最差单周等指标。如果这些指标从🟢简单到💀炼狱单调递增，说明模型的分类是有效的。"波动倍数"列以简单模式为基准=1.00x，显示各等级相对于最安全时期的波动放大程度。
A9: 风险状态 | B9: 周数 | C9: 占比 | D9: 年化波动率 | E9: 平均|周收益| | F9: 周跌>3%占比 | G9: 最差单周 | H9: 波动倍数vs简单
A10: 🟢 简单模式 | B10: =COUNTIF(评分与状态_周度!E278:E1545,评分与状态_周度!$A$7) | C10: =B10/$B$4 | D10: {=IFERROR(SQRT((B10*SUMPRODUCT((评分与状态_周度!E278:E1545=评分与状态_周度!$A$7)*回测_周度!C262:C1529*回测_周度!C262:C1529)-SUMPRODUCT((评分与状态_周度!E278:E1545=评分与状态_周度!$A$7)*回测_周度!C262:C1529)^2)/(B10*(B10-1))*52),"")} | E10: {=IFERROR(SUMPRODUCT((评分与状态_周度!E278:E1545=评分与状态_周度!$A$7)*ABS(回测_周度!C262:C1529))/B10,"")} | F10: =IFERROR(COUNTIFS(评分与状态_周度!E278:E1545,评分与状态_周度!$A$7,回测_周度!C262:C1529,"<-0.03")/B10,"") | G10: =IFERROR(_xlfn.MINIFS(回测_周度!C262:C1529,评分与状态_周度!E278:E1545,评分与状态_周度!$A$7),"") | H10: —
A11: 🟢 普通模式 | B11: =COUNTIF(评分与状态_周度!E278:E1545,评分与状态_周度!$A$8) | C11: =B11/$B$4 | D11: {=IFERROR(SQRT((B11*SUMPRODUCT((评分与状态_周度!E278:E1545=评分与状态_周度!$A$8)*回测_周度!C262:C1529*回测_周度!C262:C1529)-SUMPRODUCT((评分与状态_周度!E278:E1545=评分与状态_周度!$A$8)*回测_周度!C262:C1529)^2)/(B11*(B11-1))*52),"")} | E11: {=IFERROR(SUMPRODUCT((评分与状态_周度!E278:E1545=评分与状态_周度!$A$8)*ABS(回测_周度!C262:C1529))/B11,"")} | F11: =IFERROR(COUNTIFS(评分与状态_周度!E278:E1545,评分与状态_周度!$A$8,回测_周度!C262:C1529,"<-0.03")/B11,"") | G11: =IFERROR(_xlfn.MINIFS(回测_周度!C262:C1529,评分与状态_周度!E278:E1545,评分与状态_周度!$A$8),"") | H11: =IFERROR(D11/D$10,"")
A12: 🟡 困难模式 | B12: =COUNTIF(评分与状态_周度!E278:E1545,评分与状态_周度!$A$9) | C12: =B12/$B$4 | D12: {=IFERROR(SQRT((B12*SUMPRODUCT((评分与状态_周度!E278:E1545=评分与状态_周度!$A$9)*回测_周度!C262:C1529*回测_周度!C262:C1529)-SUMPRODUCT((评分与状态_周度!E278:E1545=评分与状态_周度!$A$9)*回测_周度!C262:C1529)^2)/(B12*(B12-1))*52),"")} | E12: {=IFERROR(SUMPRODUCT((评分与状态_周度!E278:E1545=评分与状态_周度!$A$9)*ABS(回测_周度!C262:C1529))/B12,"")} | F12: =IFERROR(COUNTIFS(评分与状态_周度!E278:E1545,评分与状态_周度!$A$9,回测_周度!C262:C1529,"<-0.03")/B12,"") | G12: =IFERROR(_xlfn.MINIFS(回测_周度!C262:C1529,评分与状态_周度!E278:E1545,评分与状态_周度!$A$9),"") | H12: =IFERROR(D12/D$10,"")
A13: 🟠 噩梦模式 | B13: =COUNTIF(评分与状态_周度!E278:E1545,评分与状态_周度!$A$10) | C13: =B13/$B$4 | D13: {=IFERROR(SQRT((B13*SUMPRODUCT((评分与状态_周度!E278:E1545=评分与状态_周度!$A$10)*回测_周度!C262:C1529*回测_周度!C262:C1529)-SUMPRODUCT((评分与状态_周度!E278:E1545=评分与状态_周度!$A$10)*回测_周度!C262:C1529)^2)/(B13*(B13-1))*52),"")} | E13: {=IFERROR(SUMPRODUCT((评分与状态_周度!E278:E1545=评分与状态_周度!$A$10)*ABS(回测_周度!C262:C1529))/B13,"")} | F13: =IFERROR(COUNTIFS(评分与状态_周度!E278:E1545,评分与状态_周度!$A$10,回测_周度!C262:C1529,"<-0.03")/B13,"") | G13: =IFERROR(_xlfn.MINIFS(回测_周度!C262:C1529,评分与状态_周度!E278:E1545,评分与状态_周度!$A$10),"") | H13: =IFERROR(D13/D$10,"")
A14: 🔴 地狱模式 | B14: =COUNTIF(评分与状态_周度!E278:E1545,评分与状态_周度!$A$11) | C14: =B14/$B$4 | D14: {=IFERROR(SQRT((B14*SUMPRODUCT((评分与状态_周度!E278:E1545=评分与状态_周度!$A$11)*回测_周度!C262:C1529*回测_周度!C262:C1529)-SUMPRODUCT((评分与状态_周度!E278:E1545=评分与状态_周度!$A$11)*回测_周度!C262:C1529)^2)/(B14*(B14-1))*52),"")} | E14: {=IFERROR(SUMPRODUCT((评分与状态_周度!E278:E1545=评分与状态_周度!$A$11)*ABS(回测_周度!C262:C1529))/B14,"")} | F14: =IFERROR(COUNTIFS(评分与状态_周度!E278:E1545,评分与状态_周度!$A$11,回测_周度!C262:C1529,"<-0.03")/B14,"") | G14: =IFERROR(_xlfn.MINIFS(回测_周度!C262:C1529,评分与状态_周度!E278:E1545,评分与状态_周度!$A$11),"") | H14: =IFERROR(D14/D$10,"")
A15: 💀 炼狱模式 | B15: =COUNTIF(评分与状态_周度!E278:E1545,评分与状态_周度!$A$12) | C15: =B15/$B$4 | D15: {=IFERROR(SQRT((B15*SUMPRODUCT((评分与状态_周度!E278:E1545=评分与状态_周度!$A$12)*回测_周度!C262:C1529*回测_周度!C262:C1529)-SUMPRODUCT((评分与状态_周度!E278:E1545=评分与状态_周度!$A$12)*回测_周度!C262:C1529)^2)/(B15*(B15-1))*52),"")} | E15: {=IFERROR(SUMPRODUCT((评分与状态_周度!E278:E1545=评分与状态_周度!$A$12)*ABS(回测_周度!C262:C1529))/B15,"")} | F15: =IFERROR(COUNTIFS(评分与状态_周度!E278:E1545,评分与状态_周度!$A$12,回测_周度!C262:C1529,"<-0.03")/B15,"") | G15: =IFERROR(_xlfn.MINIFS(回测_周度!C262:C1529,评分与状态_周度!E278:E1545,评分与状态_周度!$A$12),"") | H15: =IFERROR(D15/D$10,"")
A16: 全部 | B16: =SUM(B10:B15) | C16: =B16/$B$4 | D16: =STDEV(回测_周度!C262:C1529)*SQRT(52) | E16: {=AVERAGE(ABS(回测_周度!C262:C1529))} | F16: =COUNTIF(回测_周度!C262:C1529,"<-0.03")/B16 | G16: =MIN(回测_周度!C262:C1529)
A18: ✅ 单调性检验：波动率从简单模式的10.8%递增至炼狱模式的25.8%（2.38倍），周跌>3%频率从2.6%升至14.9%。模型准确区分了不同操作难度的市场环境。
A20: 二、误报分析 — 模型说“难”但市场其实很平静的情况有多少？
A21: 误报的定义：模型判定为"地狱模式"或"炼狱模式"（目标仓位仅15%-35%），但当周市场实际表现平稳（周收益绝对值<1.5%，即无明显方向性波动）。误报的代价是"踏空"——模型让你减仓了，但市场并没有出事，你错过了本可以满仓享受的温和收益。误报率越低越好，但需要与漏报率权衡：过度降低误报往往会增加漏报。
A23: 指标 | B23: 数值
A24: 高风险总周数（地狱+炼狱） | B24: =B14+B15
A25: 其中市场实际平稳的周数 | B25: {=SUMPRODUCT(((评分与状态_周度!E278:E1545=评分与状态_周度!$A$11)+(评分与状态_周度!E278:E1545=评分与状态_周度!$A$12))*(ABS(回测_周度!C262:C1529)<0.015))}
A26: 误报率（平稳周/高风险总周） | B26: =IFERROR(B25/B24,"")
A28: 误报的代价：高风险期平稳周的平均周收益 | B28: {=IFERROR(SUMPRODUCT(((评分与状态_周度!E278:E1545=评分与状态_周度!$A$11)+(评分与状态_周度!E278:E1545=评分与状态_周度!$A$12))*(ABS(回测_周度!C262:C1529)<0.015)*回测_周度!C262:C1529)/B25,"")} | C28: ← 踏空代价：这些周本可满仓享受的平均收益
A30: 三、漏报分析 — 市场真的出事时，模型是否提前预警了？
A31: 漏报的定义：市场出现了极端下跌（周跌>3%或>5%），但模型仍停留在低风险状态（🟢简单或🟢普通模式，仓位≥85%），未能提前预警。漏报的代价是"重仓挨打"——市场暴跌时你几乎满仓承受了全部损失。下方分两个阈值统计：>3%覆盖所有显著下跌（约占总周数的7%），>5%聚焦严重冲击事件。同时展示大跌在6个风险等级中的分布，理想情况下大跌应集中在高风险等级（说明模型在大跌时已经减仓）。
A33: 阈值：周跌幅 > 3%
A34: 指标 | B34: 数值
A35: 周跌>3%总次数 | B35: =COUNTIF(回测_周度!C262:C1529,"<-0.03")
A36: 其中模型处于低风险（简单+普通） | B36: =COUNTIFS(回测_周度!C262:C1529,"<-0.03",评分与状态_周度!E278:E1545,评分与状态_周度!$A$7)+COUNTIFS(回测_周度!C262:C1529,"<-0.03",评分与状态_周度!E278:E1545,评分与状态_周度!$A$8)
A37: 漏报率 | B37: =IFERROR(B36/B35,"") | C37: ← 越低越好：极端下跌时模型未预警的比例
A39: 阈值：周跌幅 > 5%（严重冲击）
A40: 指标 | B40: 数值
A41: 周跌>5%总次数 | B41: =COUNTIF(回测_周度!C262:C1529,"<-0.05")
A42: 其中模型处于低风险（简单+普通） | B42: =COUNTIFS(回测_周度!C262:C1529,"<-0.05",评分与状态_周度!E278:E1545,评分与状态_周度!$A$7)+COUNTIFS(回测_周度!C262:C1529,"<-0.05",评分与状态_周度!E278:E1545,评分与状态_周度!$A$8)
A43: 漏报率 | B43: =IFERROR(B42/B41,"")
A45: 大跌时各风险状态分布（周跌>3%）
A46: 风险状态 | B46: 大跌次数 | C46: 占比
A47: 🟢 简单模式 | B47: =COUNTIFS(回测_周度!C262:C1529,"<-0.03",评分与状态_周度!E278:E1545,评分与状态_周度!$A$7) | C47: =IFERROR(B47/$B$35,"")
A48: 🟢 普通模式 | B48: =COUNTIFS(回测_周度!C262:C1529,"<-0.03",评分与状态_周度!E278:E1545,评分与状态_周度!$A$8) | C48: =IFERROR(B48/$B$35,"")
A49: 🟡 困难模式 | B49: =COUNTIFS(回测_周度!C262:C1529,"<-0.03",评分与状态_周度!E278:E1545,评分与状态_周度!$A$9) | C49: =IFERROR(B49/$B$35,"")
A50: 🟠 噩梦模式 | B50: =COUNTIFS(回测_周度!C262:C1529,"<-0.03",评分与状态_周度!E278:E1545,评分与状态_周度!$A$10) | C50: =IFERROR(B50/$B$35,"")
...

Sheet 信号可视化
S2: 📊 SP500 × 操作难度信号
S3: “彩色色带 = 模型判定的风险等级。看色带和SP500走势的配合度：红色区间是否对应跌市，绿色区间是否对应涨市。”
S5: • 绿/蓝色带：简单/普通模式，市场平稳，可满仓操作
S6: • 黄/橙色带：困难/噩梦模式，波动加剧，应减仓
S7: • 红/暗红色带：地狱/炼狱模式，危机环境，仅保留底仓
S39: 📊 市场风险总览
S40: “蓝线和红线重叠 = 正常；红线飙升 = 否决权触发。”
S42: • 蓝线（纯评分）：5个特征的加权平均，反映市场“底噪”水平
S43: • 红线（否决权评分）：任一特征z>2时被拉高至该特征值，类似“紧急拉闸”
S44: • 粉色面积（回撤）：红线尖峰与回撤深度是否同步，是检验模型的核心视角
S46: 关注点：2008、2020、2025三次危机中红线是否领先于粉色回撤出现？
S67: 📊 纯综合评分
... S117: 理想情况：评分飙升→减仓→回撤来临时已轻仓。这是模型的核心价值。

Sheet 回测_周度
A1: 日期 | B1: 标普500 | C1: 标普周收益率 | D1: 滞后仓位 | E1: 策略收益 | F1: 策略NAV | G1: 买入持有NAV | H1: 策略滚动最高 | I1: 策略回撤 | J1: 持有滚动最高 | K1: 持有回撤
A2: =原始数据_周度!A2 | B2: =原始数据_周度!B2 | C2: ="" | D2: ="" | E2: =IF(OR(D2="",C2=""),"",D2*C2) | F2: ="" | G2: ="" | H2: =IF(F2="","",F2) | I2: =IF(OR(F2="",H2=""),"",F2/H2-1) | J2: =IF(G2="","",G2) | K2: =IF(OR(G2="",J2=""),"",G2/J2-1)
A3: =原始数据_周度!A3 | B3: =原始数据_周度!B3 | C3: =IFERROR(B3/B2-1,"") | D3: =IFERROR(评分与状态_周度!F19,"") | E3: =IF(OR(D3="",C3=""),"",D3*C3) | F3: =IF(E3="","",IF(F2="",1,F2*(1+E3))) | G3: =IF(E3="","",IF(G2="",1,G2*(1+C3))) | H3: =IF(F3="","",IF(H2="",F3,MAX(H2,F3))) | I3: =IF(OR(F3="",H3=""),"",F3/H3-1) | J3: =IF(G3="","",G3) | K3: =IF(OR(G3="",J3=""),"",G3/J3-1)
A4: =原始数据_周度!A4 | B4: =原始数据_周度!B4 | C4: =IFERROR(B4/B3-1,"") | D4: =IFERROR(评分与状态_周度!F20,"") | E4: =IF(OR(D4="",C4=""),"",D4*C4) | F4: =IF(E4="","",IF(F3="",1,F3*(1+E4))) | G4: =IF(E4="","",IF(G3="",1,G3*(1+C4))) | H4: =IF(F4="","",IF(H3="",F4,MAX(H3,F4))) | I4: =IF(OR(F4="",H4=""),"",F4/H4-1) | J4: =IF(G4="","",IF(J3="",G4,MAX(J3,G4))) | K4: =IF(OR(G4="",J4=""),"",G4/J4-1)
A5: =原始数据_周度!A5 | B5: =原始数据_周度!B5 | C5: =IFERROR(B5/B4-1,"") | D5: =IFERROR(评分与状态_周度!F21,"") | E5: =IF(OR(D5="",C5=""),"",D5*C5) | F5: =IF(E5="","",IF(F4="",1,F4*(1+E5))) | G5: =IF(E5="","",IF(G4="",1,G4*(1+C5))) | H5: =IF(F5="","",IF(H4="",F5,MAX(H4,F5))) | I5: =IF(OR(F5="",H5=""),"",F5/H5-1)
A6: =原始数据_周度!A6 | B6: =原始数据_周度!B6 | C6: =IFERROR(B6/B5-1,"") | D6: =IFERROR(评分与状态_周度!F22,"") | E6: =IF(OR(D6="",C6=""),"",D6*C6) | F6: =IF(E6="","",IF(F5="",1,F5*(1+E6))) | G6: =IF(E6="","",IF(G5="",1,G5*(1+C6))) | H6: =IF(F6="","",IF(H5="",F6,MAX(H5,F6))) | I6: =IF(OR(F6="",H6=""),"",F6/H6-1)
A7: =原始数据_周度!A7 | B7: =原始数据_周度!B7 | C7: =IFERROR(B7/B6-1,"") | D7: =IFERROR(评分与状态_周度!F23,"") | E7: =IF(OR(D7="",C7=""),"",D7*C7) | F7: =IF(E7="","",IF(F6="",1,F6*(1+E7))) | G7: =IF(E7="","",IF(G6="",1,G6*(1+C7))) | H7: =IF(F7="","",IF(H6="",F7,MAX(H6,F7))) | I7: =IF(OR(F7="",H7=""),"",F7/H7-1)
A8: =原始数据_周度!A8 | B8: =原始数据_周度!B8 | C8: =IFERROR(B8/B7-1,"") | D8: =IFERROR(评分与状态_周度!F24,"") | E8: =IF(OR(D8="",C8=""),"",D8*C8) | F8: =IF(E8="","",IF(F7="",1,F7*(1+E8))) | G8: =IF(E8="","",IF(G7="",1,G7*(1+C8))) | H8: =IF(F8="","",IF(H7="",F8,MAX(H7,F8))) | I8: =IF(OR(F8="",H8=""),"",F8/H8-1)
A9: =原始数据_周度!A9 | B9: =原始数据_周度!B9 | C9: =IFERROR(B9/B8-1,"") | D9: =IFERROR(评分与状态_周度!F25,"") | E9: =IF(OR(D9="",C9=""),"",D9*C9) | F9: =IF(E9="","",IF(F8="",1,F8*(1+E9))) | G9: =IF(E9="","",IF(G8="",1,G8*(1+C9))) | H9: =IF(F9="","",IF(H8="",F9,MAX(H8,F9))) | I9: =IF(OR(F9="",H9=""),"",F9/H9-1)
A10: =原始数据_周度!A10 | B10: =原始数据_周度!B10 | C10: =IFERROR(B10/B9-1,"") | D10: =IFERROR(评分与状态_周度!F26,"") | E10: =IF(OR(D10="",C10=""),"",D10*C10) | F10: =IF(E10="","",IF(F9="",1,F9*(1+E10))) | G10: =IF(E10="","",IF(G9="",1,G9*(1+C10))) | H10: =IF(F10="","",IF(H9="",F10,MAX(H9,F10))) | I10: =IF(OR(F10="",H10=""),"",F10/H10-1)
A11: =原始数据_周度!A11 | B11: =原始数据_周度!B11 | C11: =IFERROR(B11/B10-1,"") | D11: =IFERROR(评分与状态_周度!F27,"") | E11: =IF(OR(D11="",C11=""),"",D11*C11) | F11: =IF(E11="","",IF(F10="",1,F10*(1+E11))) | G11: =IF(E11="","",IF(G10="",1,G10*(1+C11))) | H11: =IF(F11="","",IF(H10="",F11,MAX(H10,F11))) | I11: =IF(OR(F11="",H11=""),"",F11/H11-1)
A12: =原始数据_周度!A12 | B12: =原始数据_周度!B12 | C12: =IFERROR(B12/B11-1,"") | D12: =IFERROR(评分与状态_周度!F28,"") | E12: =IF(OR(D12="",C12=""),"",D12*C12) | F12: =IF(E12="","",IF(F11="",1,F11*(1+E12))) | G12: =IF(E12="","",IF(G11="",1,G11*(1+C12))) | H12: =IF(F12="","",IF(H11="",F12,MAX(H11,F12))) | I12: =IF(OR(F12="",H12=""),"",F12/H12-1)
A13: =原始数据_周度!A13 | B13: =原始数据_周度!B13 | C13: =IFERROR(B13/B12-1,"") | D13: =IFERROR(评分与状态_周度!F29,"") | E13: =IF(OR(D13="",C13=""),"",D13*C13) | F13: =IF(E13="","",IF(F12="",1,F12*(1+E13))) | G13: =IF(E13="","",IF(G12="",1,G12*(1+C13))) | H13: =IF(F13="","",IF(H12="",F13,MAX(H12,F13))) | I13: =IF(OR(F13="",H13=""),"",F13/H13-1)
A14: =原始数据_周度!A14 | B14: =原始数据_周度!B14 | C14: =IFERROR(B14/B13-1,"") | D14: =IFERROR(评分与状态_周度!F30,"") | E14: =IF(OR(D14="",C14=""),"",D14*C14) | F14: =IF(E14="","",IF(F13="",1,F13*(1+E14))) | G14: =IF(E14="","",IF(G13="",1,G13*(1+C14))) | H14: =IF(F14="","",IF(H13="",F14,MAX(H13,F14))) | I14: =IF(OR(F14="",H14=""),"",F14/H14-1)
A15: =原始数据_周度!A15 | B15: =原始数据_周度!B15 | C15: =IFERROR(B15/B14-1,"") | D15: =IFERROR(评分与状态_周度!F31,"") | E15: =IF(OR(D15="",C15=""),"",D15*C15) | F15: =IF(E15="","",IF(F14="",1,F14*(1+E15))) | G15: =IF(E15="","",IF(G14="",1,G14*(1+C15))) | H15: =IF(F15="","",IF(H14="",F15,MAX(H14,F15))) | I15: =IF(OR(F15="",H15=""),"",F15/H15-1)
A16: =原始数据_周度!A16 | B16: =原始数据_周度!B16 | C16: =IFERROR(B16/B15-1,"") | D16: =IFERROR(评分与状态_周度!F32,"") | E16: =IF(OR(D16="",C16=""),"",D16*C16) | F16: =IF(E16="","",IF(F15="",1,F15*(1+E16))) | G16: =IF(E16="","",IF(G15="",1,G15*(1+C16))) | H16: =IF(F16="","",IF(H15="",F16,MAX(H15,F16))) | I16: =IF(OR(F16="",H16=""),"",F16/H16-1)
... A419: =原始数据_周度!A419 | B419: =原始数据_周度!B419 | C419: =IFERROR(B419/B418-1,"") | D419: =IFERROR(评分与状态_周度!F435,"") | E419: =IF(OR(D419="",C419=""),"",D419*C419) | F419: =IF(E419="","",IF(F418="",1,F418*(1+E419))) | G419: =IF(E419="","",IF(G418="",1,G418*(1+C419))) | H419: =IF(F419="","",IF(H418="",F419,MAX(H418,F419))) | I419: =IF(OR(F419="",H419=""),"",F419/H419-1)
A420: =原始数据_周度!A420 | B420: =原始数据_周度!B420 | C420: =IFERROR(B420/B419-1,"") | D420: =IFERROR(评分与状态_周度!F436,"") | E420: =IF(OR(D420="",C420=""),"",D420*C420) | F420: =IF(E420="","",IF(F419="",1,F419*(1+E420))) | G420: =IF(E420="","",IF(G419="",1,G419*(1+C420))) | H420: =IF(F420="","",IF(H419="",F420,MAX(H419,F420))) | I420: =IF(OR(F420="",H420=""),"",F420/H420-1) | J420: =IF(G420="","",IF(J419="",G420,MAX(J419,G420))) | K420: =IF(OR(G420="",J420=""),"",G420/J420-1)
A421: =原始数据_周度!A421 | B421: =原始数据_周度!B421 | C421: =IFERROR(B421/B420-1,"") | D421: =IFERROR(评分与状态_周度!F437,"") | E421: =IF(OR(D421="",C421=""),"",D421*C421) | F421: =IF(E421="","",IF(F420="",1,F420*(1+E421))) | G421: =IF(E421="","",IF(G420="",1,G420*(1+C421))) | H421: =IF(F421="","",IF(H420="",F421,MAX(H420,F421))) | I421: =IF(OR(F421="",H421=""),"",F421/H421-1) | J421: =IF(G421="","",IF(J420="",G421,MAX(J420,G421))) | K421: =IF(OR(G421="",J421=""),"",G421/J421-1)
A422: =原始数据_周度!A422 | B422: =原始数据_周度!B422 | C422: =IFERROR(B422/B421-1,"") | D422: =IFERROR(评分与状态_周度!F438,"") | E422: =IF(OR(D422="",C422=""),"",D422*C422) | F422: =IF(E422="","",IF(F421="",1,F421*(1+E422))) | G422: =IF(E422="","",IF(G421="",1,G421*(1+C422))) | H422: =IF(F422="","",IF(H421="",F422,MAX(H421,F422))) | I422: =IF(OR(F422="",H422=""),"",F422/H422-1) | J422: =IF(G422="","",IF(J421="",G422,MAX(J421,G422))) | K422: =IF(OR(G422="",J422=""),"",G422/J422-1)
A423: =原始数据_周度!A423 | B423: =原始数据_周度!B423 | C423: =IFERROR(B423/B422-1,"") | D423: =IFERROR(评分与状态_周度!F439,"") | E423: =IF(OR(D423="",C423=""),"",D423*C423) | F423: =IF(E423="","",IF(F422="",1,F422*(1+E423))) | G423: =IF(E423="","",IF(G422="",1,G422*(1+C423))) | H423: =IF(F423="","",IF(H422="",F423,MAX(H422,F423))) | I423: =IF(OR(F423="",H423=""),"",F423/H423-1) | J423: =IF(G423="","",IF(J422="",G423,MAX(J422,G423))) | K423: =IF(OR(G423="",J423=""),"",G423/J423-1)
A424: =原始数据_周度!A424 | B424: =原始数据_周度!B424 | C424: =IFERROR(B424/B423-1,"") | D424: =IFERROR(评分与状态_周度!F440,"") | E424: =IF(OR(D424="",C424=""),"",D424*C424) | F424: =IF(E424="","",IF(F423="",1,F423*(1+E424))) | G424: =IF(E424="","",IF(G423="",1,G423*(1+C424))) | H424: =IF(F424="","",IF(H423="",F424,MAX(H423,F424))) | I424: =IF(OR(F424="",H424=""),"",F424/H424-1) | J424: =IF(G424="","",IF(J423="",G424,MAX(J423,G424))) | K424: =IF(OR(G424="",J424=""),"",G424/J424-1)
A425: =原始数据_周度!A425 | B425: =原始数据_周度!B425 | C425: =IFERROR(B425/B424-1,"") | D425: =IFERROR(评分与状态_周度!F441,"") | E425: =IF(OR(D425="",C425=""),"",D425*C425) | F425: =IF(E425="","",IF(F424="",1,F424*(1+E425))) | G425: =IF(E425="","",IF(G424="",1,G424*(1+C425))) | H425: =IF(F425="","",IF(H424="",F425,MAX(H424,F425))) | I425: =IF(OR(F425="",H425=""),"",F425/H425-1) | J425: =IF(G425="","",IF(J424="",G425,MAX(J424,G425))) | K425: =IF(OR(G425="",J425=""),"",G425/J425-1)
A426: =原始数据_周度!A426 | B426: =原始数据_周度!B426 | C426: =IFERROR(B426/B425-1,"") | D426: =IFERROR(评分与状态_周度!F442,"") | E426: =IF(OR(D426="",C426=""),"",D426*C426) | F426: =IF(E426="","",IF(F425="",1,F425*(1+E426))) | G426: =IF(E426="","",IF(G425="",1,G425*(1+C426))) | H426: =IF(F426="","",IF(H425="",F426,MAX(H425,F426))) | I426: =IF(OR(F426="",H426=""),"",F426/H426-1) | J426: =IF(G426="","",IF(J425="",G426,MAX(J425,G426))) | K426: =IF(OR(G426="",J426=""),"",G426/J426-1)
A427: =原始数据_周度!A427 | B427: =原始数据_周度!B427 | C427: =IFERROR(B427/B426-1,"") | D427: =IFERROR(评分与状态_周度!F443,"") | E427: =IF(OR(D427="",C427=""),"",D427*C427) | F427: =IF(E427="","",IF(F426="",1,F426*(1+E427))) | G427: =IF(E427="","",IF(G426="",1,G426*(1+C427))) | H427: =IF(F427="","",IF(H426="",F427,MAX(H426,F427))) | I427: =IF(OR(F427="",H427=""),"",F427/H427-1) | J427: =IF(G427="","",IF(J426="",G427,MAX(J426,G427))) | K427: =IF(OR(G427="",J427=""),"",G427/J427-1)
A428: =原始数据_周度!A428 | B428: =原始数据_周度!B428 | C428: =IFERROR(B428/B427-1,"") | D428: =IFERROR(评分与状态_周度!F444,"") | E428: =IF(OR(D428="",C428=""),"",D428*C428) | F428: =IF(E428="","",IF(F427="",1,F427*(1+E428))) | G428: =IF(E428="","",IF(G427="",1,G427*(1+C428))) | H428: =IF(F428="","",IF(H427="",F428,MAX(H427,F428))) | I428: =IF(OR(F428="",H428=""),"",F428/H428-1) | J428: =IF(G428="","",IF(J427="",G428,MAX(J427,G428))) | K428: =IF(OR(G428="",J428=""),"",G428/J428-1)
A429: =原始数据_周度!A429 | B429: =原始数据_周度!B429 | C429: =IFERROR(B429/B428-1,"") | D429: =IFERROR(评分与状态_周度!F445,"") | E429: =IF(OR(D429="",C429=""),"",D429*C429) | F429: =IF(E429="","",IF(F428="",1,F428*(1+E429))) | G429: =IF(E429="","",IF(G428="",1,G428*(1+C429))) | H429: =IF(F429="","",IF(H428="",F429,MAX(H428,F429))) | I429: =IF(OR(F429="",H429=""),"",F429/H429-1) | J429: =IF(G429="","",IF(J428="",G429,MAX(J428,G429))) | K429: =IF(OR(G429="",J429=""),"",G429/J429-1)
A430: =原始数据_周度!A430 | B430: =原始数据_周度!B430 | C430: =IFERROR(B430/B429-1,"") | D430: =IFERROR(评分与状态_周度!F446,"") | E430: =IF(OR(D430="",C430=""),"",D430*C430) | F430: =IF(E430="","",IF(F429="",1,F429*(1+E430))) | G430: =IF(E430="","",IF(G429="",1,G429*(1+C430))) | H430: =IF(F430="","",IF(H429="",F430,MAX(H429,F430))) | I430: =IF(OR(F430="",H430=""),"",F430/H430-1) | J430: =IF(G430="","",IF(J429="",G430,MAX(J429,G430))) | K430: =IF(OR(G430="",J430=""),"",G430/J430-1)
A431: =原始数据_周度!A431 | B431: =原始数据_周度!B431 | C431: =IFERROR(B431/B430-1,"") | D431: =IFERROR(评分与状态_周度!F447,"") | E431: =IF(OR(D431="",C431=""),"",D431*C431) | F431: =IF(E431="","",IF(F430="",1,F430*(1+E431))) | G431: =IF(E431="","",IF(G430="",1,G430*(1+C431))) | H431: =IF(F431="","",IF(H430="",F431,MAX(H430,F431))) | I431: =IF(OR(F431="",H431=""),"",F431/H431-1) | J431: =IF(G431="","",IF(J430="",G431,MAX(J430,G431))) | K431: =IF(OR(G431="",J431=""),"",G431/J431-1)
... A1529: =原始数据_周度!A1529 | B1529: =原始数据_周度!B1529 | C1529: =IFERROR(B1529/B1528-1,"") | D1529: =IFERROR(评分与状态_周度!F1545,"") | E1529: =IF(OR(D1529="",C1529=""),"",D1529*C1529) | F1529: =IF(E1529="","",IF(F1528="",1,F1528*(1+E1529))) | G1529: =IF(E1529="","",IF(G1528="",1,G1528*(1+C1529))) | H1529: =IF(F1529="","",IF(H1528="",F1529,MAX(H1528,F1529))) | I1529: =IF(OR(F1529="",H1529=""),"",F1529/H1529-1) | J1529: =IF(G1529="","",IF(J1528="",G1529,MAX(J1528,G1529))) | K1529: =IF(OR(G1529="",J1529=""),"",G1529/J1529-1)

Sheet 评分与状态_周度
A1: 特征权重（可编辑）
A2: VIX_z分数 | B2: 高收益变化_z分数 | C2: 期限利差反转_z | D2: 标普趋势反转_z | E2: 均线斜率反转_z | F2: 盈利上修_z分数 | I2: 仓位缓冲参数
A3: 0.24 | B3: 0.24 | C3: 0.14 | D3: 0.14 | E3: 0.19 | F3: =SUM(A3:E3)+F3 | I3: 1
I4: 0.15
A5: 状态阈值与目标仓位（可编辑） | I5: 0.05
A6: 操作难度 | B6: 下限百分位 | C6: 上限百分位
A7: 🟢 简单模式 | B7: 0 | C7: 0.2
A8: 🟢 普通模式 | B8: 0.2 | C8: 0.4
A9: 🟡 困难模式 | B9: 0.4 | C9: 0.55
A10: 🟠 噩梦模式 | B10: 0.55 | C10: 0.7
A11: 🔴 地狱模式 | B11: 0.7 | C11: 0.85
A12: 💀 炼狱模式 | B12: 0.85 | C12: 1
A14: 否决权规则（可编辑）
A15: 单特征z-score否决阈值 | B15: 2 | C15: 任一特征z-score超过此值 → 直接判定为高风险，无视综合评分
A16: 超跌拐头减免（可编辑）
A17: 超跌阈值(偏离度) | B17: -0.1 | C17: 回看窗口(周) | D17: 8 | E17: 反弹确认(%)
A18: 日期 | B18: 综合评分 | C18: P20(滚动364周) | D18: P85(滚动364周) | E18: 风险状态 | G18: 否决权 | H18: 超跌拐头 | I18: 盈利上修仓位缓冲
A19: =特征计算_周度!A2 | B19: =IFERROR($A$3*特征计算_周度!B19+$B$3*特征计算_周度!C19+$C$3*特征计算_周度!D19+$D$3*特征计算_周度!E19+$E$3*特征计算_周度!F19+$F$3*特征计算_周度!H19,"") | C19: =IFERROR(PERCENTILE(OFFSET(B19,1-364,0,364,1),$C$7),"") | D19: =IFERROR(PERCENTILE(OFFSET(B19,1-364,0,364,1),$C$11),"") | E19: =_xlfn.LET(_xlpm.initState,IF(OR(B19="",C19=""),"",IF(OR(特征计算_周度!B2>$B$15,特征计算_周度!C2>$B$15,特征计算_周度!G2>$B$15,特征计算_周度!E2>$B$15,特征计算_周度!F2>$B$15),$A$12,IFERROR(IF(B19<PERCENTILE(OFFSET(B19,1-364,0,364,1),$C$7),$A$7,IF(B19<PERCENTILE(OFFSET(B19,1-364,0,364,1),$C$8),$A$8,IF(B19<PERCENTILE(OFFSET(B19,1-364,0,364,1),$C$9),$A$9,IF(B19<PERCENTILE(OFFSET(B19,1-364,0,364,1),$C$10),$A$10,IF(B19<PERCENTILE(OFFSET(B19,1-364,0,364,1),$C$11),$A$11,$A$12))))),""))),_xlpm.dev,原始数据_周度!G2,_xlpm.minDev,MIN(OFFSET(原始数据_周度!G2,1-$D$17,0,$D$17,1)),_xlpm.bounce,_xlpm.dev-_xlpm.minDev,_xlpm.oversold,AND(ISNUMBER(_xlpm.dev),ISNUMBER(_xlpm.minDev),_xlpm.minDev<=$B$17,_xlpm.bounce>=$F$17,OR(_xlpm.initState=$A$12,_xlpm.initState=$A$11,_xlpm.initState=$A$10)),_xlpm.pctOnly,IFERROR(IF(B19<PERCENTILE(OFFSET(B19,1-364,0,364,1),$C$7),$A$7,IF(B19<PERCENTILE(OFFSET(B19,1-364,0,364,1),$C$8),$A$8,IF(B19<PERCENTILE(OFFSET(B19,1-364,0,364,1),$C$9),$A$9,IF(B19<PERCENTILE(OFFSET(B19,1-364,0,364,1),$C$10),$A$10,IF(B19<PERCENTILE(OFFSET(B19,1-364,0,364,1),$C$11),$A$11,$A$12))))),""),IF(_xlpm.initState="","",IF(_xlpm.oversold,_xlpm.pctOnly,_xlpm.initState))) | G19: =IF(OR(B19="",C19=""),"",IF(OR(特征计算_周度!B2>$B$15,特征计算_周度!C2>$B$15,特征计算_周度!G2>$B$15,特征计算_周度!E2>$B$15,特征计算_周度!F2>$B$15),IF(特征计算_周度!B2>$B$15,"VIX ","")&IF(特征计算_周度!C2>$B$15,"HY ","")&IF(特征计算_周度!G2>$B$15,"Sahm ","")&IF(特征计算_周度!E2>$B$15,"趋势 ","")&IF(特征计算_周度!F2>$B$15,"斜率",""),"—")) | H19: =IF(OR(B19="",C19=""),"",_xlfn.LET(_xlpm.dev,原始数据_周度!G2,_xlpm.minDev,MIN(OFFSET(原始数据_周度!G2,1-$D$17,0,$D$17,1)),_xlpm.bounce,_xlpm.dev-_xlpm.minDev,IF(AND(ISNUMBER(_xlpm.dev),ISNUMBER(_xlpm.minDev),_xlpm.minDev<=$B$17,_xlpm.bounce>=$F$17),"✅ 触发","—"))) | I19: =IFERROR(IF(特征计算_周度!H19>$I$3,MIN($I$4,MAX(-$I$5,(特征计算_周度!H19-$I$3)*$I$4)),0),"")
A20: =特征计算_周度!A3 | B20: =IFERROR($A$3*特征计算_周度!B20+$B$3*特征计算_周度!C20+$C$3*特征计算_周度!D20+$D$3*特征计算_周度!E20+$E$3*特征计算_周度!F20+$F$3*特征计算_周度!H20,"") | C20: =IFERROR(PERCENTILE(OFFSET(B20,1-364,0,364,1),$C$7),"") | D20: =IFERROR(PERCENTILE(OFFSET(B20,1-364,0,364,1),$C$11),"") | E20: =_xlfn.LET(_xlpm.initState,IF(OR(B20="",C20=""),"",IF(OR(特征计算_周度!B3>$B$15,特征计算_周度!C3>$B$15,特征计算_周度!G3>$B$15,特征计算_周度!E3>$B$15,特征计算_周度!F3>$B$15),$A$12,IFERROR(IF(B20<PERCENTILE(OFFSET(B20,1-364,0,364,1),$C$7),$A$7,IF(B20<PERCENTILE(OFFSET(B20,1-364,0,364,1),$C$8),$A$8,IF(B20<PERCENTILE(OFFSET(B20,1-364,0,364,1),$C$9),$A$9,IF(B20<PERCENTILE(OFFSET(B20,1-364,0,364,1),$C$10),$A$10,IF(B20<PERCENTILE(OFFSET(B20,1-364,0,364,1),$C$11),$A$11,$A$12))))),""))),_xlpm.dev,原始数据_周度!G3,_xlpm.minDev,MIN(OFFSET(原始数据_周度!G3,1-$D$17,0,$D$17,1)),_xlpm.bounce,_xlpm.dev-_xlpm.minDev,_xlpm.oversold,AND(ISNUMBER(_xlpm.dev),ISNUMBER(_xlpm.minDev),_xlpm.minDev<=$B$17,_xlpm.bounce>=$F$17,OR(_xlpm.initState=$A$12,_xlpm.initState=$A$11,_xlpm.initState=$A$10)),_xlpm.pctOnly,IFERROR(IF(B20<PERCENTILE(OFFSET(B20,1-364,0,364,1),$C$7),$A$7,IF(B20<PERCENTILE(OFFSET(B20,1-364,0,364,1),$C$8),$A$8,IF(B20<PERCENTILE(OFFSET(B20,1-364,0,364,1),$C$9),$A$9,IF(B20<PERCENTILE(OFFSET(B20,1-364,0,364,1),$C$10),$A$10,IF(B20<PERCENTILE(OFFSET(B20,1-364,0,364,1),$C$11),$A$11,$A$12))))),""),IF(_xlpm.initState="","",IF(_xlpm.oversold,_xlpm.pctOnly,_xlpm.initState))) | G20: =IF(OR(B20="",C20=""),"",IF(OR(特征计算_周度!B3>$B$15,特征计算_周度!C3>$B$15,特征计算_周度!G3>$B$15,特征计算_周度!E3>$B$15,特征计算_周度!F3>$B$15),IF(特征计算_周度!B3>$B$15,"VIX ","")&IF(特征计算_周度!C3>$B$15,"HY ","")&IF(特征计算_周度!G3>$B$15,"Sahm ","")&IF(特征计算_周度!E3>$B$15,"趋势 ","")&IF(特征计算_周度!F3>$B$15,"斜率",""),"—")) | H20: =IF(OR(B20="",C20=""),"",_xlfn.LET(_xlpm.dev,原始数据_周度!G3,_xlpm.minDev,MIN(OFFSET(原始数据_周度!G3,1-$D$17,0,$D$17,1)),_xlpm.bounce,_xlpm.dev-_xlpm.minDev,IF(AND(ISNUMBER(_xlpm.dev),ISNUMBER(_xlpm.minDev),_xlpm.minDev<=$B$17,_xlpm.bounce>=$F$17),"✅ 触发","—"))) | I20: =IFERROR(IF(特征计算_周度!H20>$I$3,MIN($I$4,MAX(-$I$5,(特征计算_周度!H20-$I$3)*$I$4)),0),"")
A21: =特征计算_周度!A4 | B21: =IFERROR($A$3*特征计算_周度!B21+$B$3*特征计算_周度!C21+$C$3*特征计算_周度!D21+$D$3*特征计算_周度!E21+$E$3*特征计算_周度!F21+$F$3*特征计算_周度!H21,"") | C21: =IFERROR(PERCENTILE(OFFSET(B21,1-364,0,364,1),$C$7),"") | D21: =IFERROR(PERCENTILE(OFFSET(B21,1-364,0,364,1),$C$11),"") | E21: =_xlfn.LET(_xlpm.initState,IF(OR(B21="",C21=""),"",IF(OR(特征计算_周度!B4>$B$15,特征计算_周度!C4>$B$15,特征计算_周度!G4>$B$15,特征计算_周度!E4>$B$15,特征计算_周度!F4>$B$15),$A$12,IFERROR(IF(B21<PERCENTILE(OFFSET(B21,1-364,0,364,1),$C$7),$A$7,IF(B21<PERCENTILE(OFFSET(B21,1-364,0,364,1),$C$8),$A$8,IF(B21<PERCENTILE(OFFSET(B21,1-364,0,364,1),$C$9),$A$9,IF(B21<PERCENTILE(OFFSET(B21,1-364,0,364,1),$C$10),$A$10,IF(B21<PERCENTILE(OFFSET(B21,1-364,0,364,1),$C$11),$A$11,$A$12))))),""))),_xlpm.dev,原始数据_周度!G4,_xlpm.minDev,MIN(OFFSET(原始数据_周度!G4,1-$D$17,0,$D$17,1)),_xlpm.bounce,_xlpm.dev-_xlpm.minDev,_xlpm.oversold,AND(ISNUMBER(_xlpm.dev),ISNUMBER(_xlpm.minDev),_xlpm.minDev<=$B$17,_xlpm.bounce>=$F$17,OR(_xlpm.initState=$A$12,_xlpm.initState=$A$11,_xlpm.initState=$A$10)),_xlpm.pctOnly,IFERROR(IF(B21<PERCENTILE(OFFSET(B21,1-364,0,364,1),$C$7),$A$7,IF(B21<PERCENTILE(OFFSET(B21,1-364,0,364,1),$C$8),$A$8,IF(B21<PERCENTILE(OFFSET(B21,1-364,0,364,1),$C$9),$A$9,IF(B21<PERCENTILE(OFFSET(B21,1-364,0,364,1),$C$10),$A$10,IF(B21<PERCENTILE(OFFSET(B21,1-364,0,364,1),$C$11),$A$11,$A$12))))),""),IF(_xlpm.initState="","",IF(_xlpm.oversold,_xlpm.pctOnly,_xlpm.initState))) | G21: =IF(OR(B21="",C21=""),"",IF(OR(特征计算_周度!B4>$B$15,特征计算_周度!C4>$B$15,特征计算_周度!G4>$B$15,特征计算_周度!E4>$B$15,特征计算_周度!F4>$B$15),IF(特征计算_周度!B4>$B$15,"VIX ","")&IF(特征计算_周度!C4>$B$15,"HY ","")&IF(特征计算_周度!G4>$B$15,"Sahm ","")&IF(特征计算_周度!E4>$B$15,"趋势 ","")&IF(特征计算_周度!F4>$B$15,"斜率",""),"—")) | H21: =IF(OR(B21="",C21=""),"",_xlfn.LET(_xlpm.dev,原始数据_周度!G4,_xlpm.minDev,MIN(OFFSET(原始数据_周度!G4,1-$D$17,0,$D$17,1)),_xlpm.bounce,_xlpm.dev-_xlpm.minDev,IF(AND(ISNUMBER(_xlpm.dev),ISNUMBER(_xlpm.minDev),_xlpm.minDev<=$B$17,_xlpm.bounce>=$F$17),"✅ 触发","—"))) | I21: =IFERROR(IF(特征计算_周度!H21>$I$3,MIN($I$4,MAX(-$I$5,(特征计算_周度!H21-$I$3)*$I$4)),0),"")
A22: =特征计算_周度!A5 | B22: =IFERROR($A$3*特征计算_周度!B22+$B$3*特征计算_周度!C22+$C$3*特征计算_周度!D22+$D$3*特征计算_周度!E22+$E$3*特征计算_周度!F22+$F$3*特征计算_周度!H22,"") | C22: =IFERROR(PERCENTILE(OFFSET(B22,1-364,0,364,1),$C$7),"") | D22: =IFERROR(PERCENTILE(OFFSET(B22,1-364,0,364,1),$C$11),"") | E22: =_xlfn.LET(_xlpm.initState,IF(OR(B22="",C22=""),"",IF(OR(特征计算_周度!B5>$B$15,特征计算_周度!C5>$B$15,特征计算_周度!G5>$B$15,特征计算_周度!E5>$B$15,特征计算_周度!F5>$B$15),$A$12,IFERROR(IF(B22<PERCENTILE(OFFSET(B22,1-364,0,364,1),$C$7),$A$7,IF(B22<PERCENTILE(OFFSET(B22,1-364,0,364,1),$C$8),$A$8,IF(B22<PERCENTILE(OFFSET(B22,1-364,0,364,1),$C$9),$A$9,IF(B22<PERCENTILE(OFFSET(B22,1-364,0,364,1),$C$10),$A$10,IF(B22<PERCENTILE(OFFSET(B22,1-364,0,364,1),$C$11),$A$11,$A$12))))),""))),_xlpm.dev,原始数据_周度!G5,_xlpm.minDev,MIN(OFFSET(原始数据_周度!G5,1-$D$17,0,$D$17,1)),_xlpm.bounce,_xlpm.dev-_xlpm.minDev,_xlpm.oversold,AND(ISNUMBER(_xlpm.dev),ISNUMBER(_xlpm.minDev),_xlpm.minDev<=$B$17,_xlpm.bounce>=$F$17,OR(_xlpm.initState=$A$12,_xlpm.initState=$A$11,_xlpm.initState=$A$10)),_xlpm.pctOnly,IFERROR(IF(B22<PERCENTILE(OFFSET(B22,1-364,0,364,1),$C$7),$A$7,IF(B22<PERCENTILE(OFFSET(B22,1-364,0,364,1),$C$8),$A$8,IF(B22<PERCENTILE(OFFSET(B22,1-364,0,364,1),$C$9),$A$9,IF(B22<PERCENTILE(OFFSET(B22,1-364,0,364,1),$C$10),$A$10,IF(B22<PERCENTILE(OFFSET(B22,1-364,0,364,1),$C$11),$A$11,$A$12))))),""),IF(_xlpm.initState="","",IF(_xlpm.oversold,_xlpm.pctOnly,_xlpm.initState))) | G22: =IF(OR(B22="",C22=""),"",IF(OR(特征计算_周度!B5>$B$15,特征计算_周度!C5>$B$15,特征计算_周度!G5>$B$15,特征计算_周度!E5>$B$15,特征计算_周度!F5>$B$15),IF(特征计算_周度!B5>$B$15,"VIX ","")&IF(特征计算_周度!C5>$B$15,"HY ","")&IF(特征计算_周度!G5>$B$15,"Sahm ","")&IF(特征计算_周度!E5>$B$15,"趋势 ","")&IF(特征计算_周度!F5>$B$15,"斜率",""),"—")) | H22: =IF(OR(B22="",C22=""),"",_xlfn.LET(_xlpm.dev,原始数据_周度!G5,_xlpm.minDev,MIN(OFFSET(原始数据_周度!G5,1-$D$17,0,$D$17,1)),_xlpm.bounce,_xlpm.dev-_xlpm.minDev,IF(AND(ISNUMBER(_xlpm.dev),ISNUMBER(_xlpm.minDev),_xlpm.minDev<=$B$17,_xlpm.bounce>=$F$17),"✅ 触发","—"))) | I22: =IFERROR(IF(特征计算_周度!H22>$I$3,MIN($I$4,MAX(-$I$5,(特征计算_周度!H22-$I$3)*$I$4)),0),"")
A23: =特征计算_周度!A6 | B23: =IFERROR($A$3*特征计算_周度!B23+$B$3*特征计算_周度!C23+$C$3*特征计算_周度!D23+$D$3*特征计算_周度!E23+$E$3*特征计算_周度!F23+$F$3*特征计算_周度!H23,"") | C23: =IFERROR(PERCENTILE(OFFSET(B23,1-364,0,364,1),$C$7),"") | D23: =IFERROR(PERCENTILE(OFFSET(B23,1-364,0,364,1),$C$11),"") | E23: =_xlfn.LET(_xlpm.initState,IF(OR(B23="",C23=""),"",IF(OR(特征计算_周度!B6>$B$15,特征计算_周度!C6>$B$15,特征计算_周度!G6>$B$15,特征计算_周度!E6>$B$15,特征计算_周度!F6>$B$15),$A$12,IFERROR(IF(B23<PERCENTILE(OFFSET(B23,1-364,0,364,1),$C$7),$A$7,IF(B23<PERCENTILE(OFFSET(B23,1-364,0,364,1),$C$8),$A$8,IF(B23<PERCENTILE(OFFSET(B23,1-364,0,364,1),$C$9),$A$9,IF(B23<PERCENTILE(OFFSET(B23,1-364,0,364,1),$C$10),$A$10,IF(B23<PERCENTILE(OFFSET(B23,1-364,0,364,1),$C$11),$A$11,$A$12))))),""))),_xlpm.dev,原始数据_周度!G6,_xlpm.minDev,MIN(OFFSET(原始数据_周度!G6,1-$D$17,0,$D$17,1)),_xlpm.bounce,_xlpm.dev-_xlpm.minDev,_xlpm.oversold,AND(ISNUMBER(_xlpm.dev),ISNUMBER(_xlpm.minDev),_xlpm.minDev<=$B$17,_xlpm.bounce>=$F$17,OR(_xlpm.initState=$A$12,_xlpm.initState=$A$11,_xlpm.initState=$A$10)),_xlpm.pctOnly,IFERROR(IF(B23<PERCENTILE(OFFSET(B23,1-364,0,364,1),$C$7),$A$7,IF(B23<PERCENTILE(OFFSET(B23,1-364,0,364,1),$C$8),$A$8,IF(B23<PERCENTILE(OFFSET(B23,1-364,0,364,1),$C$9),$A$9,IF(B23<PERCENTILE(OFFSET(B23,1-364,0,364,1),$C$10),$A$10,IF(B23<PERCENTILE(OFFSET(B23,1-364,0,364,1),$C$11),$A$11,$A$12))))),""),IF(_xlpm.initState="","",IF(_xlpm.oversold,_xlpm.pctOnly,_xlpm.initState))) | G23: =IF(OR(B23="",C23=""),"",IF(OR(特征计算_周度!B6>$B$15,特征计算_周度!C6>$B$15,特征计算_周度!G6>$B$15,特征计算_周度!E6>$B$15,特征计算_周度!F6>$B$15),IF(特征计算_周度!B6>$B$15,"VIX ","")&IF(特征计算_周度!C6>$B$15,"HY ","")&IF(特征计算_周度!G6>$B$15,"Sahm ","")&IF(特征计算_周度!E6>$B$15,"趋势 ","")&IF(特征计算_周度!F6>$B$15,"斜率",""),"—")) | H23: =IF(OR(B23="",C23=""),"",_xlfn.LET(_xlpm.dev,原始数据_周度!G6,_xlpm.minDev,MIN(OFFSET(原始数据_周度!G6,1-$D$17,0,$D$17,1)),_xlpm.bounce,_xlpm.dev-_xlpm.minDev,IF(AND(ISNUMBER(_xlpm.dev),ISNUMBER(_xlpm.minDev),_xlpm.minDev<=$B$17,_xlpm.bounce>=$F$17),"✅ 触发","—"))) | I23: =IFERROR(IF(特征计算_周度!H23>$I$3,MIN($I$4,MAX(-$I$5,(特征计算_周度!H23-$I$3)*$I$4)),0),"")
A24: =特征计算_周度!A7 | B24: =IFERROR($A$3*特征计算_周度!B24+$B$3*特征计算_周度!C24+$C$3*特征计算_周度!D24+$D$3*特征计算_周度!E24+$E$3*特征计算_周度!F24+$F$3*特征计算_周度!H24,"") | C24: =IFERROR(PERCENTILE(OFFSET(B24,1-364,0,364,1),$C$7),"") | D24: =IFERROR(PERCENTILE(OFFSET(B24,1-364,0,364,1),$C$11),"") | E24: =_xlfn.LET(_xlpm.initState,IF(OR(B24="",C24=""),"",IF(OR(特征计算_周度!B7>$B$15,特征计算_周度!C7>$B$15,特征计算_周度!G7>$B$15,特征计算_周度!E7>$B$15,特征计算_周度!F7>$B$15),$A$12,IFERROR(IF(B24<PERCENTILE(OFFSET(B24,1-364,0,364,1),$C$7),$A$7,IF(B24<PERCENTILE(OFFSET(B24,1-364,0,364,1),$C$8),$A$8,IF(B24<PERCENTILE(OFFSET(B24,1-364,0,364,1),$C$9),$A$9,IF(B24<PERCENTILE(OFFSET(B24,1-364,0,364,1),$C$10),$A$10,IF(B24<PERCENTILE(OFFSET(B24,1-364,0,364,1),$C$11),$A$11,$A$12))))),""))),_xlpm.dev,原始数据_周度!G7,_xlpm.minDev,MIN(OFFSET(原始数据_周度!G7,1-$D$17,0,$D$17,1)),_xlpm.bounce,_xlpm.dev-_xlpm.minDev,_xlpm.oversold,AND(ISNUMBER(_xlpm.dev),ISNUMBER(_xlpm.minDev),_xlpm.minDev<=$B$17,_xlpm.bounce>=$F$17,OR(_xlpm.initState=$A$12,_xlpm.initState=$A$11,_xlpm.initState=$A$10)),_xlpm.pctOnly,IFERROR(IF(B24<PERCENTILE(OFFSET(B24,1-364,0,364,1),$C$7),$A$7,IF(B24<PERCENTILE(OFFSET(B24,1-364,0,364,1),$C$8),$A$8,IF(B24<PERCENTILE(OFFSET(B24,1-364,0,364,1),$C$9),$A$9,IF(B24<PERCENTILE(OFFSET(B24,1-364,0,364,1),$C$10),$A$10,IF(B24<PERCENTILE(OFFSET(B24,1-364,0,364,1),$C$11),$A$11,$A$12))))),""),IF(_xlpm.initState="","",IF(_xlpm.oversold,_xlpm.pctOnly,_xlpm.initState))) | G24: =IF(OR(B24="",C24=""),"",IF(OR(特征计算_周度!B7>$B$15,特征计算_周度!C7>$B$15,特征计算_周度!G7>$B$15,特征计算_周度!E7>$B$15,特征计算_周度!F7>$B$15),IF(特征计算_周度!B7>$B$15,"VIX ","")&IF(特征计算_周度!C7>$B$15,"HY ","")&IF(特征计算_周度!G7>$B$15,"Sahm ","")&IF(特征计算_周度!E7>$B$15,"趋势 ","")&IF(特征计算_周度!F7>$B$15,"斜率",""),"—")) | H24: =IF(OR(B24="",C24=""),"",_xlfn.LET(_xlpm.dev,原始数据_周度!G7,_xlpm.minDev,MIN(OFFSET(原始数据_周度!G7,1-$D$17,0,$D$17,1)),_xlpm.bounce,_xlpm.dev-_xlpm.minDev,IF(AND(ISNUMBER(_xlpm.dev),ISNUMBER(_xlpm.minDev),_xlpm.minDev<=$B$17,_xlpm.bounce>=$F$17),"✅ 触发","—"))) | I24: =IFERROR(IF(特征计算_周度!H24>$I$3,MIN($I$4,MAX(-$I$5,(特征计算_周度!H24-$I$3)*$I$4)),0),"")
A25: =特征计算_周度!A8 | B25: =IFERROR($A$3*特征计算_周度!B25+$B$3*特征计算_周度!C25+$C$3*特征计算_周度!D25+$D$3*特征计算_周度!E25+$E$3*特征计算_周度!F25+$F$3*特征计算_周度!H25,"") | C25: =IFERROR(PERCENTILE(OFFSET(B25,1-364,0,364,1),$C$7),"") | D25: =IFERROR(PERCENTILE(OFFSET(B25,1-364,0,364,1),$C$11),"") | E25: =_xlfn.LET(_xlpm.initState,IF(OR(B25="",C25=""),"",IF(OR(特征计算_周度!B8>$B$15,特征计算_周度!C8>$B$15,特征计算_周度!G8>$B$15,特征计算_周度!E8>$B$15,特征计算_周度!F8>$B$15),$A$12,IFERROR(IF(B25<PERCENTILE(OFFSET(B25,1-364,0,364,1),$C$7),$A$7,IF(B25<PERCENTILE(OFFSET(B25,1-364,0,364,1),$C$8),$A$8,IF(B25<PERCENTILE(OFFSET(B25,1-364,0,364,1),$C$9),$A$9,IF(B25<PERCENTILE(OFFSET(B25,1-364,0,364,1),$C$10),$A$10,IF(B25<PERCENTILE(OFFSET(B25,1-364,0,364,1),$C$11),$A$11,$A$12))))),""))),_xlpm.dev,原始数据_周度!G8,_xlpm.minDev,MIN(OFFSET(原始数据_周度!G8,1-$D$17,0,$D$17,1)),_xlpm.bounce,_xlpm.dev-_xlpm.minDev,_xlpm.oversold,AND(ISNUMBER(_xlpm.dev),ISNUMBER(_xlpm.minDev),_xlpm.minDev<=$B$17,_xlpm.bounce>=$F$17,OR(_xlpm.initState=$A$12,_xlpm.initState=$A$11,_xlpm.initState=$A$10)),_xlpm.pctOnly,IFERROR(IF(B25<PERCENTILE(OFFSET(B25,1-364,0,364,1),$C$7),$A$7,IF(B25<PERCENTILE(OFFSET(B25,1-364,0,364,1),$C$8),$A$8,IF(B25<PERCENTILE(OFFSET(B25,1-364,0,364,1),$C$9),$A$9,IF(B25<PERCENTILE(OFFSET(B25,1-364,0,364,1),$C$10),$A$10,IF(B25<PERCENTILE(OFFSET(B25,1-364,0,364,1),$C$11),$A$11,$A$12))))),""),IF(_xlpm.initState="","",IF(_xlpm.oversold,_xlpm.pctOnly,_xlpm.initState))) | G25: =IF(OR(B25="",C25=""),"",IF(OR(特征计算_周度!B8>$B$15,特征计算_周度!C8>$B$15,特征计算_周度!G8>$B$15,特征计算_周度!E8>$B$15,特征计算_周度!F8>$B$15),IF(特征计算_周度!B8>$B$15,"VIX ","")&IF(特征计算_周度!C8>$B$15,"HY ","")&IF(特征计算_周度!G8>$B$15,"Sahm ","")&IF(特征计算_周度!E8>$B$15,"趋势 ","")&IF(特征计算_周度!F8>$B$15,"斜率",""),"—")) | H25: =IF(OR(B25="",C25=""),"",_xlfn.LET(_xlpm.dev,原始数据_周度!G8,_xlpm.minDev,MIN(OFFSET(原始数据_周度!G8,1-$D$17,0,$D$17,1)),_xlpm.bounce,_xlpm.dev-_xlpm.minDev,IF(AND(ISNUMBER(_xlpm.dev),ISNUMBER(_xlpm.minDev),_xlpm.minDev<=$B$17,_xlpm.bounce>=$F$17),"✅ 触发","—"))) | I25: =IFERROR(IF(特征计算_周度!H25>$I$3,MIN($I$4,MAX(-$I$5,(特征计算_周度!H25-$I$3)*$I$4)),0),"")
A26: =特征计算_周度!A9 | B26: =IFERROR($A$3*特征计算_周度!B26+$B$3*特征计算_周度!C26+$C$3*特征计算_周度!D26+$D$3*特征计算_周度!E26+$E$3*特征计算_周度!F26+$F$3*特征计算_周度!H26,"") | C26: =IFERROR(PERCENTILE(OFFSET(B26,1-364,0,364,1),$C$7),"") | D26: =IFERROR(PERCENTILE(OFFSET(B26,1-364,0,364,1),$C$11),"") | E26: =_xlfn.LET(_xlpm.initState,IF(OR(B26="",C26=""),"",IF(OR(特征计算_周度!B9>$B$15,特征计算_周度!C9>$B$15,特征计算_周度!G9>$B$15,特征计算_周度!E9>$B$15,特征计算_周度!F9>$B$15),$A$12,IFERROR(IF(B26<PERCENTILE(OFFSET(B26,1-364,0,364,1),$C$7),$A$7,IF(B26<PERCENTILE(OFFSET(B26,1-364,0,364,1),$C$8),$A$8,IF(B26<PERCENTILE(OFFSET(B26,1-364,0,364,1),$C$9),$A$9,IF(B26<PERCENTILE(OFFSET(B26,1-364,0,364,1),$C$10),$A$10,IF(B26<PERCENTILE(OFFSET(B26,1-364,0,364,1),$C$11),$A$11,$A$12))))),""))),_xlpm.dev,原始数据_周度!G9,_xlpm.minDev,MIN(OFFSET(原始数据_周度!G9,1-$D$17,0,$D$17,1)),_xlpm.bounce,_xlpm.dev-_xlpm.minDev,_xlpm.oversold,AND(ISNUMBER(_xlpm.dev),ISNUMBER(_xlpm.minDev),_xlpm.minDev<=$B$17,_xlpm.bounce>=$F$17,OR(_xlpm.initState=$A$12,_xlpm.initState=$A$11,_xlpm.initState=$A$10)),_xlpm.pctOnly,IFERROR(IF(B26<PERCENTILE(OFFSET(B26,1-364,0,364,1),$C$7),$A$7,IF(B26<PERCENTILE(OFFSET(B26,1-364,0,364,1),$C$8),$A$8,IF(B26<PERCENTILE(OFFSET(B26,1-364,0,364,1),$C$9),$A$9,IF(B26<PERCENTILE(OFFSET(B26,1-364,0,364,1),$C$10),$A$10,IF(B26<PERCENTILE(OFFSET(B26,1-364,0,364,1),$C$11),$A$11,$A$12))))),""),IF(_xlpm.initState="","",IF(_xlpm.oversold,_xlpm.pctOnly,_xlpm.initState))) | G26: =IF(OR(B26="",C26=""),"",IF(OR(特征计算_周度!B9>$B$15,特征计算_周度!C9>$B$15,特征计算_周度!G9>$B$15,特征计算_周度!E9>$B$15,特征计算_周度!F9>$B$15),IF(特征计算_周度!B9>$B$15,"VIX ","")&IF(特征计算_周度!C9>$B$15,"HY ","")&IF(特征计算_周度!G9>$B$15,"Sahm ","")&IF(特征计算_周度!E9>$B$15,"趋势 ","")&IF(特征计算_周度!F9>$B$15,"斜率",""),"—")) | H26: =IF(OR(B26="",C26=""),"",_xlfn.LET(_xlpm.dev,原始数据_周度!G9,_xlpm.minDev,MIN(OFFSET(原始数据_周度!G9,1-$D$17,0,$D$17,1)),_xlpm.bounce,_xlpm.dev-_xlpm.minDev,IF(AND(ISNUMBER(_xlpm.dev),ISNUMBER(_xlpm.minDev),_xlpm.minDev<=$B$17,_xlpm.bounce>=$F$17),"✅ 触发","—"))) | I26: =IFERROR(IF(特征计算_周度!H26>$I$3,MIN($I$4,MAX(-$I$5,(特征计算_周度!H26-$I$3)*$I$4)),0),"")
A27: =特征计算_周度!A10 | B27: =IFERROR($A$3*特征计算_周度!B27+$B$3*特征计算_周度!C27+$C$3*特征计算_周度!D27+$D$3*特征计算_周度!E27+$E$3*特征计算_周度!F27+$F$3*特征计算_周度!H27,"") | C27: =IFERROR(PERCENTILE(OFFSET(B27,1-364,0,364,1),$C$7),"") | D27: =IFERROR(PERCENTILE(OFFSET(B27,1-364,0,364,1),$C$11),"") | E27: =_xlfn.LET(_xlpm.initState,IF(OR(B27="",C27=""),"",IF(OR(特征计算_周度!B10>$B$15,特征计算_周度!C10>$B$15,特征计算_周度!G10>$B$15,特征计算_周度!E10>$B$15,特征计算_周度!F10>$B$15),$A$12,IFERROR(IF(B27<PERCENTILE(OFFSET(B27,1-364,0,364,1),$C$7),$A$7,IF(B27<PERCENTILE(OFFSET(B27,1-364,0,364,1),$C$8),$A$8,IF(B27<PERCENTILE(OFFSET(B27,1-364,0,364,1),$C$9),$A$9,IF(B27<PERCENTILE(OFFSET(B27,1-364,0,364,1),$C$10),$A$10,IF(B27<PERCENTILE(OFFSET(B27,1-364,0,364,1),$C$11),$A$11,$A$12))))),""))),_xlpm.dev,原始数据_周度!G10,_xlpm.minDev,MIN(OFFSET(原始数据_周度!G10,1-$D$17,0,$D$17,1)),_xlpm.bounce,_xlpm.dev-_xlpm.minDev,_xlpm.oversold,AND(ISNUMBER(_xlpm.dev),ISNUMBER(_xlpm.minDev),_xlpm.minDev<=$B$17,_xlpm.bounce>=$F$17,OR(_xlpm.initState=$A$12,_xlpm.initState=$A$11,_xlpm.initState=$A$10)),_xlpm.pctOnly,IFERROR(IF(B27<PERCENTILE(OFFSET(B27,1-364,0,364,1),$C$7),$A$7,IF(B27<PERCENTILE(OFFSET(B27,1-364,0,364,1),$C$8),$A$8,IF(B27<PERCENTILE(OFFSET(B27,1-364,0,364,1),$C$9),$A$9,IF(B27<PERCENTILE(OFFSET(B27,1-364,0,364,1),$C$10),$A$10,IF(B27<PERCENTILE(OFFSET(B27,1-364,0,364,1),$C$11),$A$11,$A$12))))),""),IF(_xlpm.initState="","",IF(_xlpm.oversold,_xlpm.pctOnly,_xlpm.initState))) | G27: =IF(OR(B27="",C27=""),"",IF(OR(特征计算_周度!B10>$B$15,特征计算_周度!C10>$B$15,特征计算_周度!G10>$B$15,特征计算_周度!E10>$B$15,特征计算_周度!F10>$B$15),IF(特征计算_周度!B10>$B$15,"VIX ","")&IF(特征计算_周度!C10>$B$15,"HY ","")&IF(特征计算_周度!G10>$B$15,"Sahm ","")&IF(特征计算_周度!E10>$B$15,"趋势 ","")&IF(特征计算_周度!F10>$B$15,"斜率",""),"—")) | H27: =IF(OR(B27="",C27=""),"",_xlfn.LET(_xlpm.dev,原始数据_周度!G10,_xlpm.minDev,MIN(OFFSET(原始数据_周度!G10,1-$D$17,0,$D$17,1)),_xlpm.bounce,_xlpm.dev-_xlpm.minDev,IF(AND(ISNUMBER(_xlpm.dev),ISNUMBER(_xlpm.minDev),_xlpm.minDev<=$B$17,_xlpm.bounce>=$F$17),"✅ 触发","—"))) | I27: =IFERROR(IF(特征计算_周度!H27>$I$3,MIN($I$4,MAX(-$I$5,(特征计算_周度!H27-$I$3)*$I$4)),0),"")
A28: =特征计算_周度!A11 | B28: =IFERROR($A$3*特征计算_周度!B28+$B$3*特征计算_周度!C28+$C$3*特征计算_周度!D28+$D$3*特征计算_周度!E28+$E$3*特征计算_周度!F28+$F$3*特征计算_周度!H28,"") | C28: =IFERROR(PERCENTILE(OFFSET(B28,1-364,0,364,1),$C$7),"") | D28: =IFERROR(PERCENTILE(OFFSET(B28,1-364,0,364,1),$C$11),"") | E28: =_xlfn.LET(_xlpm.initState,IF(OR(B28="",C28=""),"",IF(OR(特征计算_周度!B11>$B$15,特征计算_周度!C11>$B$15,特征计算_周度!G11>$B$15,特征计算_周度!E11>$B$15,特征计算_周度!F11>$B$15),$A$12,IFERROR(IF(B28<PERCENTILE(OFFSET(B28,1-364,0,364,1),$C$7),$A$7,IF(B28<PERCENTILE(OFFSET(B28,1-364,0,364,1),$C$8),$A$8,IF(B28<PERCENTILE(OFFSET(B28,1-364,0,364,1),$C$9),$A$9,IF(B28<PERCENTILE(OFFSET(B28,1-364,0,364,1),$C$10),$A$10,IF(B28<PERCENTILE(OFFSET(B28,1-364,0,364,1),$C$11),$A$11,$A$12))))),""))),_xlpm.dev,原始数据_周度!G11,_xlpm.minDev,MIN(OFFSET(原始数据_周度!G11,1-$D$17,0,$D$17,1)),_xlpm.bounce,_xlpm.dev-_xlpm.minDev,_xlpm.oversold,AND(ISNUMBER(_xlpm.dev),ISNUMBER(_xlpm.minDev),_xlpm.minDev<=$B$17,_xlpm.bounce>=$F$17,OR(_xlpm.initState=$A$12,_xlpm.initState=$A$11,_xlpm.initState=$A$10)),_xlpm.pctOnly,IFERROR(IF(B28<PERCENTILE(OFFSET(B28,1-364,0,364,1),$C$7),$A$7,IF(B28<PERCENTILE(OFFSET(B28,1-364,0,364,1),$C$8),$A$8,IF(B28<PERCENTILE(OFFSET(B28,1-364,0,364,1),$C$9),$A$9,IF(B28<PERCENTILE(OFFSET(B28,1-364,0,364,1),$C$10),$A$10,IF(B28<PERCENTILE(OFFSET(B28,1-364,0,364,1),$C$11),$A$11,$A$12))))),""),IF(_xlpm.initState="","",IF(_xlpm.oversold,_xlpm.pctOnly,_xlpm.initState))) | G28: =IF(OR(B28="",C28=""),"",IF(OR(特征计算_周度!B11>$B$15,特征计算_周度!C11>$B$15,特征计算_周度!G11>$B$15,特征计算_周度!E11>$B$15,特征计算_周度!F11>$B$15),IF(特征计算_周度!B11>$B$15,"VIX ","")&IF(特征计算_周度!C11>$B$15,"HY ","")&IF(特征计算_周度!G11>$B$15,"Sahm ","")&IF(特征计算_周度!E11>$B$15,"趋势 ","")&IF(特征计算_周度!F11>$B$15,"斜率",""),"—")) | H28: =IF(OR(B28="",C28=""),"",_xlfn.LET(_xlpm.dev,原始数据_周度!G11,_xlpm.minDev,MIN(OFFSET(原始数据_周度!G11,1-$D$17,0,$D$17,1)),_xlpm.bounce,_xlpm.dev-_xlpm.minDev,IF(AND(ISNUMBER(_xlpm.dev),ISNUMBER(_xlpm.minDev),_xlpm.minDev<=$B$17,_xlpm.bounce>=$F$17),"✅ 触发","—"))) | I28: =IFERROR(IF(特征计算_周度!H28>$I$3,MIN($I$4,MAX(-$I$5,(特征计算_周度!H28-$I$3)*$I$4)),0),"")
A29: =特征计算_周度!A12 | B29: =IFERROR($A$3*特征计算_周度!B29+$B$3*特征计算_周度!C29+$C$3*特征计算_周度!D29+$D$3*特征计算_周度!E29+$E$3*特征计算_周度!F29+$F$3*特征计算_周度!H29,"") | C29: =IFERROR(PERCENTILE(OFFSET(B29,1-364,0,364,1),$C$7),"") | D29: =IFERROR(PERCENTILE(OFFSET(B29,1-364,0,364,1),$C$11),"") | E29: =_xlfn.LET(_xlpm.initState,IF(OR(B29="",C29=""),"",IF(OR(特征计算_周度!B12>$B$15,特征计算_周度!C12>$B$15,特征计算_周度!G12>$B$15,特征计算_周度!E12>$B$15,特征计算_周度!F12>$B$15),$A$12,IFERROR(IF(B29<PERCENTILE(OFFSET(B29,1-364,0,364,1),$C$7),$A$7,IF(B29<PERCENTILE(OFFSET(B29,1-364,0,364,1),$C$8),$A$8,IF(B29<PERCENTILE(OFFSET(B29,1-364,0,364,1),$C$9),$A$9,IF(B29<PERCENTILE(OFFSET(B29,1-364,0,364,1),$C$10),$A$10,IF(B29<PERCENTILE(OFFSET(B29,1-364,0,364,1),$C$11),$A$11,$A$12))))),""))),_xlpm.dev,原始数据_周度!G12,_xlpm.minDev,MIN(OFFSET(原始数据_周度!G12,1-$D$17,0,$D$17,1)),_xlpm.bounce,_xlpm.dev-_xlpm.minDev,_xlpm.oversold,AND(ISNUMBER(_xlpm.dev),ISNUMBER(_xlpm.minDev),_xlpm.minDev<=$B$17,_xlpm.bounce>=$F$17,OR(_xlpm.initState=$A$12,_xlpm.initState=$A$11,_xlpm.initState=$A$10)),_xlpm.pctOnly,IFERROR(IF(B29<PERCENTILE(OFFSET(B29,1-364,0,364,1),$C$7),$A$7,IF(B29<PERCENTILE(OFFSET(B29,1-364,0,364,1),$C$8),$A$8,IF(B29<PERCENTILE(OFFSET(B29,1-364,0,364,1),$C$9),$A$9,IF(B29<PERCENTILE(OFFSET(B29,1-364,0,364,1),$C$10),$A$10,IF(B29<PERCENTILE(OFFSET(B29,1-364,0,364,1),$C$11),$A$11,$A$12))))),""),IF(_xlpm.initState="","",IF(_xlpm.oversold,_xlpm.pctOnly,_xlpm.initState))) | G29: =IF(OR(B29="",C29=""),"",IF(OR(特征计算_周度!B12>$B$15,特征计算_周度!C12>$B$15,特征计算_周度!G12>$B$15,特征计算_周度!E12>$B$15,特征计算_周度!F12>$B$15),IF(特征计算_周度!B12>$B$15,"VIX ","")&IF(特征计算_周度!C12>$B$15,"HY ","")&IF(特征计算_周度!G12>$B$15,"Sahm ","")&IF(特征计算_周度!E12>$B$15,"趋势 ","")&IF(特征计算_周度!F12>$B$15,"斜率",""),"—")) | H29: =IF(OR(B29="",C29=""),"",_xlfn.LET(_xlpm.dev,原始数据_周度!G12,_xlpm.minDev,MIN(OFFSET(原始数据_周度!G12,1-$D$17,0,$D$17,1)),_xlpm.bounce,_xlpm.dev-_xlpm.minDev,IF(AND(ISNUMBER(_xlpm.dev),ISNUMBER(_xlpm.minDev),_xlpm.minDev<=$B$17,_xlpm.bounce>=$F$17),"✅ 触发","—"))) | I29: =IFERROR(IF(特征计算_周度!H29>$I$3,MIN($I$4,MAX(-$I$5,(特征计算_周度!H29-$I$3)*$I$4)),0),"")
A30: =特征计算_周度!A13 | B30: =IFERROR($A$3*特征计算_周度!B30+$B$3*特征计算_周度!C30+$C$3*特征计算_周度!D30+$D$3*特征计算_周度!E30+$E$3*特征计算_周度!F30+$F$3*特征计算_周度!H30,"") | C30: =IFERROR(PERCENTILE(OFFSET(B30,1-364,0,364,1),$C$7),"") | D30: =IFERROR(PERCENTILE(OFFSET(B30,1-364,0,364,1),$C$11),"") | E30: =_xlfn.LET(_xlpm.initState,IF(OR(B30="",C30=""),"",IF(OR(特征计算_周度!B13>$B$15,特征计算_周度!C13>$B$15,特征计算_周度!G13>$B$15,特征计算_周度!E13>$B$15,特征计算_周度!F13>$B$15),$A$12,IFERROR(IF(B30<PERCENTILE(OFFSET(B30,1-364,0,364,1),$C$7),$A$7,IF(B30<PERCENTILE(OFFSET(B30,1-364,0,364,1),$C$8),$A$8,IF(B30<PERCENTILE(OFFSET(B30,1-364,0,364,1),$C$9),$A$9,IF(B30<PERCENTILE(OFFSET(B30,1-364,0,364,1),$C$10),$A$10,IF(B30<PERCENTILE(OFFSET(B30,1-364,0,364,1),$C$11),$A$11,$A$12))))),""))),_xlpm.dev,原始数据_周度!G13,_xlpm.minDev,MIN(OFFSET(原始数据_周度!G13,1-$D$17,0,$D$17,1)),_xlpm.bounce,_xlpm.dev-_xlpm.minDev,_xlpm.oversold,AND(ISNUMBER(_xlpm.dev),ISNUMBER(_xlpm.minDev),_xlpm.minDev<=$B$17,_xlpm.bounce>=$F$17,OR(_xlpm.initState=$A$12,_xlpm.initState=$A$11,_xlpm.initState=$A$10)),_xlpm.pctOnly,IFERROR(IF(B30<PERCENTILE(OFFSET(B30,1-364,0,364,1),$C$7),$A$7,IF(B30<PERCENTILE(OFFSET(B30,1-364,0,364,1),$C$8),$A$8,IF(B30<PERCENTILE(OFFSET(B30,1-364,0,364,1),$C$9),$A$9,IF(B30<PERCENTILE(OFFSET(B30,1-364,0,364,1),$C$10),$A$10,IF(B30<PERCENTILE(OFFSET(B30,1-364,0,364,1),$C$11),$A$11,$A$12))))),""),IF(_xlpm.initState="","",IF(_xlpm.oversold,_xlpm.pctOnly,_xlpm.initState))) | G30: =IF(OR(B30="",C30=""),"",IF(OR(特征计算_周度!B13>$B$15,特征计算_周度!C13>$B$15,特征计算_周度!G13>$B$15,特征计算_周度!E13>$B$15,特征计算_周度!F13>$B$15),IF(特征计算_周度!B13>$B$15,"VIX ","")&IF(特征计算_周度!C13>$B$15,"HY ","")&IF(特征计算_周度!G13>$B$15,"Sahm ","")&IF(特征计算_周度!E13>$B$15,"趋势 ","")&IF(特征计算_周度!F13>$B$15,"斜率",""),"—")) | H30: =IF(OR(B30="",C30=""),"",_xlfn.LET(_xlpm.dev,原始数据_周度!G13,_xlpm.minDev,MIN(OFFSET(原始数据_周度!G13,1-$D$17,0,$D$17,1)),_xlpm.bounce,_xlpm.dev-_xlpm.minDev,IF(AND(ISNUMBER(_xlpm.dev),ISNUMBER(_xlpm.minDev),_xlpm.minDev<=$B$17,_xlpm.bounce>=$F$17),"✅ 触发","—"))) | I30: =IFERROR(IF(特征计算_周度!H30>$I$3,MIN($I$4,MAX(-$I$5,(特征计算_周度!H30-$I$3)*$I$4)),0),"")
... A1546: =特征计算_周度!A1529 | B1546: =IFERROR($A$3*特征计算_周度!B1546+$B$3*特征计算_周度!C1546+$C$3*特征计算_周度!D1546+$D$3*特征计算_周度!E1546+$E$3*特征计算_周度!F1546+$F$3*特征计算_周度!H1546,"") | C1546: =IFERROR(PERCENTILE(OFFSET(B1546,1-364,0,364,1),$C$7),"") | D1546: =IFERROR(PERCENTILE(OFFSET(B1546,1-364,0,364,1),$C$11),"") | E1546: =_xlfn.LET(_xlpm.initState,IF(OR(B1546="",C1546=""),"",IF(OR(特征计算_周度!B1529>$B$15,特征计算_周度!C1529>$B$15,特征计算_周度!G1529>$B$15,特征计算_周度!E1529>$B$15,特征计算_周度!F1529>$B$15),$A$12,IFERROR(IF(B1546<PERCENTILE(OFFSET(B1546,1-364,0,364,1),$C$7),$A$7,IF(B1546<PERCENTILE(OFFSET(B1546,1-364,0,364,1),$C$8),$A$8,IF(B1546<PERCENTILE(OFFSET(B1546,1-364,0,364,1),$C$9),$A$9,IF(B1546<PERCENTILE(OFFSET(B1546,1-364,0,364,1),$C$10),$A$10,IF(B1546<PERCENTILE(OFFSET(B1546,1-364,0,364,1),$C$11),$A$11,$A$12))))),""))),_xlpm.dev,原始数据_周度!G1529,_xlpm.minDev,MIN(OFFSET(原始数据_周度!G1529,1-$D$17,0,$D$17,1)),_xlpm.bounce,_xlpm.dev-_xlpm.minDev,_xlpm.oversold,AND(ISNUMBER(_xlpm.dev),ISNUMBER(_xlpm.minDev),_xlpm.minDev<=$B$17,_xlpm.bounce>=$F$17,OR(_xlpm.initState=$A$12,_xlpm.initState=$A$11,_xlpm.initState=$A$10)),_xlpm.pctOnly,IFERROR(IF(B1546<PERCENTILE(OFFSET(B1546,1-364,0,364,1),$C$7),$A$7,IF(B1546<PERCENTILE(OFFSET(B1546,1-364,0,364,1),$C$8),$A$8,IF(B1546<PERCENTILE(OFFSET(B1546,1-364,0,364,1),$C$9),$A$9,IF(B1546<PERCENTILE(OFFSET(B1546,1-364,0,364,1),$C$10),$A$10,IF(B1546<PERCENTILE(OFFSET(B1546,1-364,0,364,1),$C$11),$A$11,$A$12))))),""),IF(_xlpm.initState="","",IF(_xlpm.oversold,_xlpm.pctOnly,_xlpm.initState))) | G1546: =IF(OR(B1546="",C1546=""),"",IF(OR(特征计算_周度!B1529>$B$15,特征计算_周度!C1529>$B$15,特征计算_周度!G1529>$B$15,特征计算_周度!E1529>$B$15,特征计算_周度!F1529>$B$15),IF(特征计算_周度!B1529>$B$15,"VIX ","")&IF(特征计算_周度!C1529>$B$15,"HY ","")&IF(特征计算_周度!G1529>$B$15,"Sahm ","")&IF(特征计算_周度!E1529>$B$15,"趋势 ","")&IF(特征计算_周度!F1529>$B$15,"斜率",""),"—")) | H1546: =IF(OR(B1546="",C1546=""),"",_xlfn.LET(_xlpm.dev,原始数据_周度!G1529,_xlpm.minDev,MIN(OFFSET(原始数据_周度!G1529,1-$D$17,0,$D$17,1)),_xlpm.bounce,_xlpm.dev-_xlpm.minDev,IF(AND(ISNUMBER(_xlpm.dev),ISNUMBER(_xlpm.minDev),_xlpm.minDev<=$B$17,_xlpm.bounce>=$F$17),"✅ 触发","—"))) | I1546: =IFERROR(IF(特征计算_周度!H1546>$I$3,MIN($I$4,MAX(-$I$5,(特征计算_周度!H1546-$I$3)*$I$4)),0),"")

Sheet 市场状态总览
A1: 市场状态总览
A3: 日期 | B3: 纯综合评分 | C3: 综合评分带否决权 | D3: SP500 | E3: SP500回撤
A4: =原始数据_周度!A2 | B4: =IF(特征计算_周度!B2="","",0.25*IF(特征计算_周度!B2="",0,特征计算_周度!B2)+0.25*IF(特征计算_周度!C2="",0,特征计算_周度!C2)+0.15*IF(特征计算_周度!D2="",0,特征计算_周度!D2)+0.15*IF(特征计算_周度!E2="",0,特征计算_周度!E2)+0.2*IF(特征计算_周度!F2="",0,特征计算_周度!F2)) | C4: =IF(B4="","",IF(OR(IF(特征计算_周度!B2="",FALSE,特征计算_周度!B2>2),IF(特征计算_周度!C2="",FALSE,特征计算_周度!C2>2),IF(特征计算_周度!G2="",FALSE,特征计算_周度!G2>2),IF(特征计算_周度!E2="",FALSE,特征计算_周度!E2>2),IF(特征计算_周度!F2="",FALSE,特征计算_周度!F2>2)),MAX(B4,MAX(IF(特征计算_周度!B2="",0,特征计算_周度!B2),IF(特征计算_周度!C2="",0,特征计算_周度!C2),IF(特征计算_周度!G2="",0,特征计算_周度!G2),IF(特征计算_周度!E2="",0,特征计算_周度!E2),IF(特征计算_周度!F2="",0,特征计算_周度!F2))),B4)) | D4: =原始数据_周度!B2 | E4: =IF(D4="","",D4/MAX(D$4:D4)-1)
A5: =原始数据_周度!A3 | B5: =IF(特征计算_周度!B3="","",0.25*IF(特征计算_周度!B3="",0,特征计算_周度!B3)+0.25*IF(特征计算_周度!C3="",0,特征计算_周度!C3)+0.15*IF(特征计算_周度!D3="",0,特征计算_周度!D3)+0.15*IF(特征计算_周度!E3="",0,特征计算_周度!E3)+0.2*IF(特征计算_周度!F3="",0,特征计算_周度!F3)) | C5: =IF(B5="","",IF(OR(IF(特征计算_周度!B3="",FALSE,特征计算_周度!B3>2),IF(特征计算_周度!C3="",FALSE,特征计算_周度!C3>2),IF(特征计算_周度!G3="",FALSE,特征计算_周度!G3>2),IF(特征计算_周度!E3="",FALSE,特征计算_周度!E3>2),IF(特征计算_周度!F3="",FALSE,特征计算_周度!F3>2)),MAX(B5,MAX(IF(特征计算_周度!B3="",0,特征计算_周度!B3),IF(特征计算_周度!C3="",0,特征计算_周度!C3),IF(特征计算_周度!G3="",0,特征计算_周度!G3),IF(特征计算_周度!E3="",0,特征计算_周度!E3),IF(特征计算_周度!F3="",0,特征计算_周度!F3))),B5)) | D5: =原始数据_周度!B3 | E5: =IF(D5="","",D5/MAX(D$4:D5)-1)
A6: =原始数据_周度!A4 | B6: =IF(特征计算_周度!B4="","",0.25*IF(特征计算_周度!B4="",0,特征计算_周度!B4)+0.25*IF(特征计算_周度!C4="",0,特征计算_周度!C4)+0.15*IF(特征计算_周度!D4="",0,特征计算_周度!D4)+0.15*IF(特征计算_周度!E4="",0,特征计算_周度!E4)+0.2*IF(特征计算_周度!F4="",0,特征计算_周度!F4)) | C6: =IF(B6="","",IF(OR(IF(特征计算_周度!B4="",FALSE,特征计算_周度!B4>2),IF(特征计算_周度!C4="",FALSE,特征计算_周度!C4>2),IF(特征计算_周度!G4="",FALSE,特征计算_周度!G4>2),IF(特征计算_周度!E4="",FALSE,特征计算_周度!E4>2),IF(特征计算_周度!F4="",FALSE,特征计算_周度!F4>2)),MAX(B6,MAX(IF(特征计算_周度!B4="",0,特征计算_周度!B4),IF(特征计算_周度!C4="",0,特征计算_周度!C4),IF(特征计算_周度!G4="",0,特征计算_周度!G4),IF(特征计算_周度!E4="",0,特征计算_周度!E4),IF(特征计算_周度!F4="",0,特征计算_周度!F4))),B6)) | D6: =原始数据_周度!B4 | E6: =IF(D6="","",D6/MAX(D$4:D6)-1)
A7: =原始数据_周度!A5 | B7: =IF(特征计算_周度!B5="","",0.25*IF(特征计算_周度!B5="",0,特征计算_周度!B5)+0.25*IF(特征计算_周度!C5="",0,特征计算_周度!C5)+0.15*IF(特征计算_周度!D5="",0,特征计算_周度!D5)+0.15*IF(特征计算_周度!E5="",0,特征计算_周度!E5)+0.2*IF(特征计算_周度!F5="",0,特征计算_周度!F5)) | C7: =IF(B7="","",IF(OR(IF(特征计算_周度!B5="",FALSE,特征计算_周度!B5>2),IF(特征计算_周度!C5="",FALSE,特征计算_周度!C5>2),IF(特征计算_周度!G5="",FALSE,特征计算_周度!G5>2),IF(特征计算_周度!E5="",FALSE,特征计算_周度!E5>2),IF(特征计算_周度!F5="",FALSE,特征计算_周度!F5>2)),MAX(B7,MAX(IF(特征计算_周度!B5="",0,特征计算_周度!B5),IF(特征计算_周度!C5="",0,特征计算_周度!C5),IF(特征计算_周度!G5="",0,特征计算_周度!G5),IF(特征计算_周度!E5="",0,特征计算_周度!E5),IF(特征计算_周度!F5="",0,特征计算_周度!F5))),B7)) | D7: =原始数据_周度!B5 | E7: =IF(D7="","",D7/MAX(D$4:D7)-1)
A8: =原始数据_周度!A6 | B8: =IF(特征计算_周度!B6="","",0.25*IF(特征计算_周度!B6="",0,特征计算_周度!B6)+0.25*IF(特征计算_周度!C6="",0,特征计算_周度!C6)+0.15*IF(特征计算_周度!D6="",0,特征计算_周度!D6)+0.15*IF(特征计算_周度!E6="",0,特征计算_周度!E6)+0.2*IF(特征计算_周度!F6="",0,特征计算_周度!F6)) | C8: =IF(B8="","",IF(OR(IF(特征计算_周度!B6="",FALSE,特征计算_周度!B6>2),IF(特征计算_周度!C6="",FALSE,特征计算_周度!C6>2),IF(特征计算_周度!G6="",FALSE,特征计算_周度!G6>2),IF(特征计算_周度!E6="",FALSE,特征计算_周度!E6>2),IF(特征计算_周度!F6="",FALSE,特征计算_周度!F6>2)),MAX(B8,MAX(IF(特征计算_周度!B6="",0,特征计算_周度!B6),IF(特征计算_周度!C6="",0,特征计算_周度!C6),IF(特征计算_周度!G6="",0,特征计算_周度!G6),IF(特征计算_周度!E6="",0,特征计算_周度!E6),IF(特征计算_周度!F6="",0,特征计算_周度!F6))),B8)) | D8: =原始数据_周度!B6 | E8: =IF(D8="","",D8/MAX(D$4:D8)-1)
A9: =原始数据_周度!A7 | B9: =IF(特征计算_周度!B7="","",0.25*IF(特征计算_周度!B7="",0,特征计算_周度!B7)+0.25*IF(特征计算_周度!C7="",0,特征计算_周度!C7)+0.15*IF(特征计算_周度!D7="",0,特征计算_周度!D7)+0.15*IF(特征计算_周度!E7="",0,特征计算_周度!E7)+0.2*IF(特征计算_周度!F7="",0,特征计算_周度!F7)) | C9: =IF(B9="","",IF(OR(IF(特征计算_周度!B7="",FALSE,特征计算_周度!B7>2),IF(特征计算_周度!C7="",FALSE,特征计算_周度!C7>2),IF(特征计算_周度!G7="",FALSE,特征计算_周度!G7>2),IF(特征计算_周度!E7="",FALSE,特征计算_周度!E7>2),IF(特征计算_周度!F7="",FALSE,特征计算_周度!F7>2)),MAX(B9,MAX(IF(特征计算_周度!B7="",0,特征计算_周度!B7),IF(特征计算_周度!C7="",0,特征计算_周度!C7),IF(特征计算_周度!G7="",0,特征计算_周度!G7),IF(特征计算_周度!E7="",0,特征计算_周度!E7),IF(特征计算_周度!F7="",0,特征计算_周度!F7))),B9)) | D9: =原始数据_周度!B7 | E9: =IF(D9="","",D9/MAX(D$4:D9)-1)
A10: =原始数据_周度!A8 | B10: =IF(特征计算_周度!B8="","",0.25*IF(特征计算_周度!B8="",0,特征计算_周度!B8)+0.25*IF(特征计算_周度!C8="",0,特征计算_周度!C8)+0.15*IF(特征计算_周度!D8="",0,特征计算_周度!D8)+0.15*IF(特征计算_周度!E8="",0,特征计算_周度!E8)+0.2*IF(特征计算_周度!F8="",0,特征计算_周度!F8)) | C10: =IF(B10="","",IF(OR(IF(特征计算_周度!B8="",FALSE,特征计算_周度!B8>2),IF(特征计算_周度!C8="",FALSE,特征计算_周度!C8>2),IF(特征计算_周度!G8="",FALSE,特征计算_周度!G8>2),IF(特征计算_周度!E8="",FALSE,特征计算_周度!E8>2),IF(特征计算_周度!F8="",FALSE,特征计算_周度!F8>2)),MAX(B10,MAX(IF(特征计算_周度!B8="",0,特征计算_周度!B8),IF(特征计算_周度!C8="",0,特征计算_周度!C8),IF(特征计算_周度!G8="",0,特征计算_周度!G8),IF(特征计算_周度!E8="",0,特征计算_周度!E8),IF(特征计算_周度!F8="",0,特征计算_周度!F8))),B10)) | D10: =原始数据_周度!B8 | E10: =IF(D10="","",D10/MAX(D$4:D10)-1)
A11: =原始数据_周度!A9 | B11: =IF(特征计算_周度!B9="","",0.25*IF(特征计算_周度!B9="",0,特征计算_周度!B9)+0.25*IF(特征计算_周度!C9="",0,特征计算_周度!C9)+0.15*IF(特征计算_周度!D9="",0,特征计算_周度!D9)+0.15*IF(特征计算_周度!E9="",0,特征计算_周度!E9)+0.2*IF(特征计算_周度!F9="",0,特征计算_周度!F9)) | C11: =IF(B11="","",IF(OR(IF(特征计算_周度!B9="",FALSE,特征计算_周度!B9>2),IF(特征计算_周度!C9="",FALSE,特征计算_周度!C9>2),IF(特征计算_周度!G9="",FALSE,特征计算_周度!G9>2),IF(特征计算_周度!E9="",FALSE,特征计算_周度!E9>2),IF(特征计算_周度!F9="",FALSE,特征计算_周度!F9>2)),MAX(B11,MAX(IF(特征计算_周度!B9="",0,特征计算_周度!B9),IF(特征计算_周度!C9="",0,特征计算_周度!C9),IF(特征计算_周度!G9="",0,特征计算_周度!G9),IF(特征计算_周度!E9="",0,特征计算_周度!E9),IF(特征计算_周度!F9="",0,特征计算_周度!F9))),B11)) | D11: =原始数据_周度!B9 | E11: =IF(D11="","",D11/MAX(D$4:D11)-1)
A12: =原始数据_周度!A10 | B12: =IF(特征计算_周度!B10="","",0.25*IF(特征计算_周度!B10="",0,特征计算_周度!B10)+0.25*IF(特征计算_周度!C10="",0,特征计算_周度!C10)+0.15*IF(特征计算_周度!D10="",0,特征计算_周度!D10)+0.15*IF(特征计算_周度!E10="",0,特征计算_周度!E10)+0.2*IF(特征计算_周度!F10="",0,特征计算_周度!F10)) | C12: =IF(B12="","",IF(OR(IF(特征计算_周度!B10="",FALSE,特征计算_周度!B10>2),IF(特征计算_周度!C10="",FALSE,特征计算_周度!C10>2),IF(特征计算_周度!G10="",FALSE,特征计算_周度!G10>2),IF(特征计算_周度!E10="",FALSE,特征计算_周度!E10>2),IF(特征计算_周度!F10="",FALSE,特征计算_周度!F10>2)),MAX(B12,MAX(IF(特征计算_周度!B10="",0,特征计算_周度!B10),IF(特征计算_周度!C10="",0,特征计算_周度!C10),IF(特征计算_周度!G10="",0,特征计算_周度!G10),IF(特征计算_周度!E10="",0,特征计算_周度!E10),IF(特征计算_周度!F10="",0,特征计算_周度!F10))),B12)) | D12: =原始数据_周度!B10 | E12: =IF(D12="","",D12/MAX(D$4:D12)-1)
A13: =原始数据_周度!A11 | B13: =IF(特征计算_周度!B11="","",0.25*IF(特征计算_周度!B11="",0,特征计算_周度!B11)+0.25*IF(特征计算_周度!C11="",0,特征计算_周度!C11)+0.15*IF(特征计算_周度!D11="",0,特征计算_周度!D11)+0.15*IF(特征计算_周度!E11="",0,特征计算_周度!E11)+0.2*IF(特征计算_周度!F11="",0,特征计算_周度!F11)) | C13: =IF(B13="","",IF(OR(IF(特征计算_周度!B11="",FALSE,特征计算_周度!B11>2),IF(特征计算_周度!C11="",FALSE,特征计算_周度!C11>2),IF(特征计算_周度!G11="",FALSE,特征计算_周度!G11>2),IF(特征计算_周度!E11="",FALSE,特征计算_周度!E11>2),IF(特征计算_周度!F11="",FALSE,特征计算_周度!F11>2)),MAX(B13,MAX(IF(特征计算_周度!B11="",0,特征计算_周度!B11),IF(特征计算_周度!C11="",0,特征计算_周度!C11),IF(特征计算_周度!G11="",0,特征计算_周度!G11),IF(特征计算_周度!E11="",0,特征计算_周度!E11),IF(特征计算_周度!F11="",0,特征计算_周度!F11))),B13)) | D13: =原始数据_周度!B11 | E13: =IF(D13="","",D13/MAX(D$4:D13)-1)
A14: =原始数据_周度!A12 | B14: =IF(特征计算_周度!B12="","",0.25*IF(特征计算_周度!B12="",0,特征计算_周度!B12)+0.25*IF(特征计算_周度!C12="",0,特征计算_周度!C12)+0.15*IF(特征计算_周度!D12="",0,特征计算_周度!D12)+0.15*IF(特征计算_周度!E12="",0,特征计算_周度!E12)+0.2*IF(特征计算_周度!F12="",0,特征计算_周度!F12)) | C14: =IF(B14="","",IF(OR(IF(特征计算_周度!B12="",FALSE,特征计算_周度!B12>2),IF(特征计算_周度!C12="",FALSE,特征计算_周度!C12>2),IF(特征计算_周度!G12="",FALSE,特征计算_周度!G12>2),IF(特征计算_周度!E12="",FALSE,特征计算_周度!E12>2),IF(特征计算_周度!F12="",FALSE,特征计算_周度!F12>2)),MAX(B14,MAX(IF(特征计算_周度!B12="",0,特征计算_周度!B12),IF(特征计算_周度!C12="",0,特征计算_周度!C12),IF(特征计算_周度!G12="",0,特征计算_周度!G12),IF(特征计算_周度!E12="",0,特征计算_周度!E12),IF(特征计算_周度!F12="",0,特征计算_周度!F12))),B14)) | D14: =原始数据_周度!B12 | E14: =IF(D14="","",D14/MAX(D$4:D14)-1)
A15: =原始数据_周度!A13 | B15: =IF(特征计算_周度!B13="","",0.25*IF(特征计算_周度!B13="",0,特征计算_周度!B13)+0.25*IF(特征计算_周度!C13="",0,特征计算_周度!C13)+0.15*IF(特征计算_周度!D13="",0,特征计算_周度!D13)+0.15*IF(特征计算_周度!E13="",0,特征计算_周度!E13)+0.2*IF(特征计算_周度!F13="",0,特征计算_周度!F13)) | C15: =IF(B15="","",IF(OR(IF(特征计算_周度!B13="",FALSE,特征计算_周度!B13>2),IF(特征计算_周度!C13="",FALSE,特征计算_周度!C13>2),IF(特征计算_周度!G13="",FALSE,特征计算_周度!G13>2),IF(特征计算_周度!E13="",FALSE,特征计算_周度!E13>2),IF(特征计算_周度!F13="",FALSE,特征计算_周度!F13>2)),MAX(B15,MAX(IF(特征计算_周度!B13="",0,特征计算_周度!B13),IF(特征计算_周度!C13="",0,特征计算_周度!C13),IF(特征计算_周度!G13="",0,特征计算_周度!G13),IF(特征计算_周度!E13="",0,特征计算_周度!E13),IF(特征计算_周度!F13="",0,特征计算_周度!F13))),B15)) | D15: =原始数据_周度!B13 | E15: =IF(D15="","",D15/MAX(D$4:D15)-1)
... A1531: =原始数据_周度!A1529 | B1531: =IF(特征计算_周度!B1529="","",0.25*IF(特征计算_周度!B1529="",0,特征计算_周度!B1529)+0.25*IF(特征计算_周度!C1529="",0,特征计算_周度!C1529)+0.15*IF(特征计算_周度!D1529="",0,特征计算_周度!D1529)+0.15*IF(特征计算_周度!E1529="",0,特征计算_周度!E1529)+0.2*IF(特征计算_周度!F1529="",0,特征计算_周度!F1529)) | C1531: =IF(B1531="","",IF(OR(IF(特征计算_周度!B1529="",FALSE,特征计算_周度!B1529>2),IF(特征计算_周度!C1529="",FALSE,特征计算_周度!C1529>2),IF(特征计算_周度!G1529="",FALSE,特征计算_周度!G1529>2),IF(特征计算_周度!E1529="",FALSE,特征计算_周度!E1529>2),IF(特征计算_周度!F1529="",FALSE,特征计算_周度!F1529>2)),MAX(B1531,MAX(IF(特征计算_周度!B1529="",0,特征计算_周度!B1529),IF(特征计算_周度!C1529="",0,特征计算_周度!C1529),IF(特征计算_周度!G1529="",0,特征计算_周度!G1529),IF(特征计算_周度!E1529="",0,特征计算_周度!E1529),IF(特征计算_周度!F1529="",0,特征计算_周度!F1529))),B1531)) | D1531: =原始数据_周度!B1529 | E1531: =IF(D1531="","",D1531/MAX(D$4:D1531)-1)

Sheet 特征计算_周度
A1: 日期 | B1: VIX_z分数 | C1: 高收益变化_z分数 | D1: 期限利差反转_z | E1: 标普趋势反转_z | F1: 均线斜率反转_z | G1: Sahm_z(否决权用) | H1: 盈利上修_z分数
A2: =原始数据_周度!A2 | B2: ="" | C2: ="" | D2: ="" | E2: ="" | F2: ="" | G2: ="" | H2: =""
A3: =原始数据_周度!A3 | B3: ="" | C3: ="" | D3: ="" | E3: ="" | F3: ="" | G3: ="" | H3: =""
A4: =原始数据_周度!A4 | B4: ="" | C4: ="" | D4: ="" | E4: ="" | F4: ="" | G4: ="" | H4: =""
A5: =原始数据_周度!A5 | B5: ="" | C5: ="" | D5: ="" | E5: ="" | F5: ="" | G5: ="" | H5: =""
A6: =原始数据_周度!A6 | B6: ="" | C6: ="" | D6: ="" | E6: ="" | F6: ="" | G6: ="" | H6: =""
A7: =原始数据_周度!A7 | B7: ="" | C7: ="" | D7: ="" | E7: ="" | F7: ="" | G7: ="" | H7: =""
A8: =原始数据_周度!A8 | B8: ="" | C8: ="" | D8: ="" | E8: ="" | F8: ="" | G8: ="" | H8: =""
A9: =原始数据_周度!A9 | B9: ="" | C9: ="" | D9: ="" | E9: ="" | F9: ="" | G9: ="" | H9: =""
A10: =原始数据_周度!A10 | B10: ="" | C10: ="" | D10: ="" | E10: ="" | F10: ="" | G10: ="" | H10: =""
A11: =原始数据_周度!A11 | B11: ="" | C11: ="" | D11: ="" | E11: ="" | F11: ="" | G11: ="" | H11: =""
A12: =原始数据_周度!A12 | B12: ="" | C12: ="" | D12: ="" | E12: ="" | F12: ="" | G12: ="" | H12: =""
A13: =原始数据_周度!A13 | B13: ="" | C13: ="" | D13: ="" | E13: ="" | F13: ="" | G13: ="" | H13: =""
... A53: =原始数据_周度!A53 | B53: ="" | C53: ="" | D53: ="" | E53: ="" | F53: ="" | G53: ="" | H53: =""
A54: =原始数据_周度!A54 | B54: ="" | C54: ="" | D54: ="" | E54: ="" | F54: ="" | G54: ="" | H54: =IFERROR((原始数据_周度!J54-AVERAGE($J$2:J54))/STDEV($J$2:J54),"")
A55: =原始数据_周度!A55 | B55: ="" | C55: ="" | D55: ="" | E55: ="" | F55: ="" | G55: ="" | H55: =IFERROR((原始数据_周度!J55-AVERAGE($J$2:J55))/STDEV($J$2:J55),"")
A56: =原始数据_周度!A56 | B56: ="" | C56: ="" | D56: ="" | E56: ="" | F56: ="" | G56: ="" | H56: =IFERROR((原始数据_周度!J56-AVERAGE($J$2:J56))/STDEV($J$2:J56),"")
A57: =原始数据_周度!A57 | B57: ="" | C57: ="" | D57: ="" | E57: ="" | F57: ="" | G57: ="" | H57: =IFERROR((原始数据_周度!J57-AVERAGE($J$2:J57))/STDEV($J$2:J57),"")
A58: =原始数据_周度!A58 | B58: ="" | C58: ="" | D58: ="" | E58: ="" | F58: ="" | G58: ="" | H58: =IFERROR((原始数据_周度!J58-AVERAGE($J$2:J58))/STDEV($J$2:J58),"")
A59: =原始数据_周度!A59 | B59: ="" | C59: ="" | D59: ="" | E59: ="" | F59: ="" | G59: ="" | H59: =IFERROR((原始数据_周度!J59-AVERAGE($J$2:J59))/STDEV($J$2:J59),"")
A60: =原始数据_周度!A60 | B60: ="" | C60: ="" | D60: ="" | E60: ="" | F60: ="" | G60: ="" | H60: =IFERROR((原始数据_周度!J60-AVERAGE($J$2:J60))/STDEV($J$2:J60),"")
A61: =原始数据_周度!A61 | B61: ="" | C61: ="" | D61: ="" | E61: ="" | F61: ="" | G61: ="" | H61: =IFERROR((原始数据_周度!J61-AVERAGE($J$2:J61))/STDEV($J$2:J61),"")
A62: =原始数据_周度!A62 | B62: ="" | C62: ="" | D62: ="" | E62: ="" | F62: ="" | G62: ="" | H62: =IFERROR((原始数据_周度!J62-AVERAGE($J$2:J62))/STDEV($J$2:J62),"")
A63: =原始数据_周度!A63 | B63: ="" | C63: ="" | D63: ="" | E63: ="" | F63: ="" | G63: ="" | H63: =IFERROR((原始数据_周度!J63-AVERAGE($J$2:J63))/STDEV($J$2:J63),"")
A64: =原始数据_周度!A64 | B64: ="" | C64: ="" | D64: ="" | E64: ="" | F64: ="" | G64: ="" | H64: =IFERROR((原始数据_周度!J64-AVERAGE($J$2:J64))/STDEV($J$2:J64),"")
A65: =原始数据_周度!A65 | B65: ="" | C65: ="" | D65: ="" | E65: ="" | F65: ="" | G65: ="" | H65: =IFERROR((原始数据_周度!J65-AVERAGE($J$2:J65))/STDEV($J$2:J65),"")
... A156: =原始数据_周度!A156 | B156: ="" | C156: ="" | D156: ="" | E156: ="" | F156: ="" | G156: ="" | H156: =IFERROR((原始数据_周度!J156-AVERAGE($J$2:J156))/STDEV($J$2:J156),"")
A157: =原始数据_周度!A157 | B157: =IFERROR((原始数据_周度!C157-AVERAGE(原始数据_周度!C2:C157))/STDEV(原始数据_周度!C2:C157),"") | C157: ="" | D157: =IFERROR(-1*(原始数据_周度!E157-AVERAGE(原始数据_周度!E2:E157))/STDEV(原始数据_周度!E2:E157),"") | E157: ="" | F157: ="" | G157: =IFERROR((原始数据_周度!I157-AVERAGE(原始数据_周度!I2:I157))/STDEV(原始数据_周度!I2:I157),"") | H157: =IFERROR((原始数据_周度!J157-AVERAGE($J$2:J157))/STDEV($J$2:J157),"")
A158: =原始数据_周度!A158 | B158: =IFERROR((原始数据_周度!C158-AVERAGE(原始数据_周度!C3:C158))/STDEV(原始数据_周度!C3:C158),"") | C158: ="" | D158: =IFERROR(-1*(原始数据_周度!E158-AVERAGE(原始数据_周度!E3:E158))/STDEV(原始数据_周度!E3:E158),"") | E158: ="" | F158: ="" | G158: =IFERROR((原始数据_周度!I158-AVERAGE(原始数据_周度!I3:I158))/STDEV(原始数据_周度!I3:I158),"") | H158: =IFERROR((原始数据_周度!J158-AVERAGE($J$2:J158))/STDEV($J$2:J158),"")
A159: =原始数据_周度!A159 | B159: =IFERROR((原始数据_周度!C159-AVERAGE(原始数据_周度!C4:C159))/STDEV(原始数据_周度!C4:C159),"") | C159: ="" | D159: =IFERROR(-1*(原始数据_周度!E159-AVERAGE(原始数据_周度!E4:E159))/STDEV(原始数据_周度!E4:E159),"") | E159: ="" | F159: ="" | G159: =IFERROR((原始数据_周度!I159-AVERAGE(原始数据_周度!I4:I159))/STDEV(原始数据_周度!I4:I159),"") | H159: =IFERROR((原始数据_周度!J159-AVERAGE($J$2:J159))/STDEV($J$2:J159),"")
A160: =原始数据_周度!A160 | B160: =IFERROR((原始数据_周度!C160-AVERAGE(原始数据_周度!C5:C160))/STDEV(原始数据_周度!C5:C160),"") | C160: ="" | D160: =IFERROR(-1*(原始数据_周度!E160-AVERAGE(原始数据_周度!E5:E160))/STDEV(原始数据_周度!E5:E160),"") | E160: ="" | F160: ="" | G160: =IFERROR((原始数据_周度!I160-AVERAGE(原始数据_周度!I5:I160))/STDEV(原始数据_周度!I5:I160),"") | H160: =IFERROR((原始数据_周度!J160-AVERAGE($J$2:J160))/STDEV($J$2:J160),"")
